Workbook

Sheet ExchangeRateVO(汇率详情)
A1: ERROR_MSG | B1: filter_flag | C1: exchangeRateType_name | D1: targetCurrencyId_name | E1: sourceCurrencyId_name | F1: quotationDate | G1: exchangeRate
A2: 错误信息 | B2: 过滤标识 | C2: *汇率类型 | D2: *目的币种 | E2: *源币种 | F2: *报价日期 | G2: *汇率
A3: X | B3: X | C3: 非空，填写汇率类型编码 | D3: 非空，参照企业账号下币种档案里的币种名称填写 | E3: 非空，参照企业账号下币种档案里的币种名称填写 | F3: 非空，请输当前汇率的报价日期 | G3: 非空，按照当前汇率类型的精度输入，多余的位数会四舍五入
A4: X | B4: X | C4: 字符,长度1024,必输 | D4: 字符,长度1024,必输 | E4: 字符,长度1024,必输 | F4: 日期,必输 | G4: 浮点型,必输
C5: 01 | D5: 卢布 | E5: 人民币 | F5: 20260701 | G5: =ROUND(1/汇总!I4,6) -> 11.5913
C6: 01 | D6: 卢布 | E6: 美元 | F6: 20260701 | G6: =ROUND(汇总!C4/汇总!I4,6) -> 78.898502
C7: 01 | D7: 美元 | E7: 泰铢 | F7: 20260701 | G7: =ROUND(汇总!K4/汇总!C4,6) -> 0.029977
C8: 01 | D8: 美元 | E8: 越南盾 | F8: 20260701 | G8: =ROUND(汇总!H4/汇总!C4,6) -> 3.8e-05 | H8: 小币种
C9: 01 | D9: 美元 | E9: 卢布 | F9: 20260701 | G9: =ROUND(汇总!I4/汇总!C4,6) -> 0.012675
C10: 01 | D10: 美元 | E10: 墨西哥比索 | F10: 20260701 | G10: =ROUND(汇总!G4/汇总!C4,6) -> 0.057134
C11: 01 | D11: 美元 | E11: 坦桑尼亚先令 | F11: 20260701 | G11: =ROUND(汇总!F4/汇总!C4,6) -> 0.000381 | H11: 小币种
C12: 01 | D12: 美元 | E12: 英镑 | F12: 20260701 | G12: =ROUND(汇总!J4/汇总!C4,6) -> 1.323343
C13: 01 | D13: 美元 | E13: 欧元 | F13: 20260701 | G13: =ROUND(汇总!L4/汇总!C4,6) -> 1.139671
C14: 01 | D14: 墨西哥比索 | E14: 人民币 | F14: 20260701 | G14: =ROUND(1/汇总!G4,6) -> 2.5714
C15: 01 | D15: 墨西哥比索 | E15: 美元 | F15: 20260701 | G15: =ROUND(汇总!C4/汇总!G4,6) -> 17.502748
C16: 01 | D16: 欧元 | E16: 英镑 | F16: 20260701 | G16: =ROUND(汇总!J4/汇总!L4,6) -> 1.161162
C17: 01 | D17: 欧元 | E17: 美元 | F17: 20260701 | G17: =ROUND(汇总!C4/汇总!L4,6) -> 0.877446
C18: 01 | D18: 欧元 | E18: 人民币 | F18: 20260701 | G18: =ROUND(1/汇总!L4,6) -> 0.128909
C19: 01 | D19: 人民币 | E19: 卢布 | F19: 20260701 | G19: =ROUND(汇总!I4,6) -> 0.086272
C20: 01 | D20: 人民币 | E20: 墨西哥比索 | F20: 20260701 | G20: =ROUND(汇总!G4,6) -> 0.388893
C21: 01 | D21: 人民币 | E21: 欧元 | F21: 20260701 | G21: =ROUND(汇总!L4,6) -> 7.7574
C22: 01 | D22: 泰铢 | E22: 美元 | F22: 20260701 | G22: =ROUND(汇总!C4/汇总!K4,6) -> 33.358956
C23: 01 | D23: 坦桑尼亚先令 | E23: 美元 | F23: 20260701 | G23: =ROUND(汇总!C4/汇总!F4,6) -> 2625 | H23: 小币种
C24: 01 | D24: 英镑 | E24: 欧元 | F24: 20260701 | G24: =ROUND(汇总!L4/汇总!J4,6) -> 0.861206
C25: 01 | D25: 英镑 | E25: 美元 | F25: 20260701 | G25: =ROUND(汇总!C4/汇总!J4,6) -> 0.755662
C26: 01 | D26: 越南盾 | E26: 美元 | F26: 20260701 | G26: =ROUND(汇总!C4/汇总!H4,6) -> 26290 | H26: 小币种
C27: 01 | D27: 人民币 | E27: 美元 | F27: 20260701 | G27: =ROUND(汇总!C4,6) -> 6.8067
C28: 01 | D28: 美元 | E28: 人民币 | F28: 20260701 | G28: =ROUND(1/汇总!C4,6) -> 0.146914
C29: 01 | D29: 人民币 | E29: 泰铢 | F29: 20260701 | G29: =ROUND(汇总!K4,6) -> 0.204044
C30: 01 | D30: 泰铢 | E30: 人民币 | F30: 20260701 | G30: =ROUND(1/汇总!K4,6) -> 4.9009
C31: 01 | D31: 欧元 | E31: 兹罗提 | F31: 20260701 | G31: =ROUND(汇总!M4/汇总!L4,6) -> 0.232776
C32: 01 | D32: 人民币 | E32: 南非兰特 | F32: 20260701 | G32: =ROUND(汇总!N4,6) -> 0.414886
C33: 01 | D33: 美元 | E33: 南非兰特 | F33: 20260701 | G33: =ROUND(汇总!N4/汇总!C4,6) -> 0.060953
C34: 01 | D34: 南非兰特 | E34: 人民币 | F34: 20260701 | G34: =ROUND(1/汇总!N4,6) -> 2.4103
C35: 01 | D35: 南非兰特 | E35: 美元 | F35: 20260701 | G35: =ROUND(汇总!C4/汇总!N4,6) -> 16.406189
C36: 01 | D36: 人民币 | E36: 越南盾 | F36: 20260701 | G36: =ROUND(汇总!H4,6) -> 0.000259 | H36: 小币种
C37: 01 | D37: 人民币 | E37: 坦桑尼亚先令 | F37: 20260701 | G37: =ROUND(汇总!F4,6) -> 0.002593 | H37: 小币种
C38: 01 | D38: 人民币 | E38: 英镑 | F38: 20260701 | G38: =ROUND(汇总!J4,6) -> 9.0076
C39: 01 | D39: 人民币 | E39: 菲律宾比索 | F39: 20260701 | G39: =ROUND(汇总!P4,6) -> 0.1111 | H39: 小币种
C40: 01 | D40: 美元 | E40: 菲律宾比索 | F40: 20260701 | G40: =ROUND(汇总!P4/汇总!C4,6) -> 0.016322 | H40: 小币种
...

Sheet 汇总
E1: =#REF!*C147 -> #REF! | F1: =#REF!*C147 -> #REF! | H1: =#REF!*C147 -> #REF!
B2: 各子公司当地货币兑人民币汇率
B3: 46204 | C3: 美国-USD | D3: 香港-HKD | E3: 印尼-IDR | F3: 坦桑-TZS | G3: 墨西哥-MXN | H3: 越南-VND | I3: 俄罗斯-RUB | J3: 英国-GBP | K3: 泰国-THB | L3: 比利时-EUR | M3: 波兰-PLN | N3: 南非-ZAR | O3: 新加坡-SGD | P3: 菲律宾-PHP | Q3: 尼日利亚-NGN | R3: 日本-JPY | S3: 加拿大-CAD | T3: 澳大利亚-AUD | U3: 马来西亚-MYR | V3: 新西兰-NZD
B4: 期初汇率 | C4: ='人民币汇率中间价（月初，月末）'!$B2/100 -> 6.8067 | D4: ='人民币汇率中间价（月初，月末）'!$E2/100 -> 0.86784 | E4: =+'印尼央行汇率-7月'!O370 -> 0.00037902908 | F4: =0.000380952380952127*C4 -> 0.0025930286 | G4: =100/'人民币汇率中间价（月初，月末）'!$Y2 -> 0.38889321 | H4: =0.0000380372765309995*C4 -> 0.00025890833 | I4: =100/'人民币汇率中间价（月初，月末）'!$N2 -> 0.0862716 | J4: ='人民币汇率中间价（月初，月末）'!$F2/100 -> 9.0076 | K4: =100/'人民币汇率中间价（月初，月末）'!$Z2 -> 0.20404416 | L4: ='人民币汇率中间价（月初，月末）'!$C2/100 -> 7.7574 | M4: =100/'人民币汇率中间价（月初，月末）'!$T2 -> 1.8057386 | N4: =100/'人民币汇率中间价（月初，月末）'!$O2 -> 0.41488611 | O4: ='人民币汇率中间价（月初，月末）'!$I2/100 -> 5.2528 | P4: =0.0163221336297023*C4 -> 0.11109987 | Q4: =0.00072393997089663*C4 -> 0.0049276422 | R4: ='人民币汇率中间价（月初，月末）'!$D2/100 -> 0.041835 | S4: ='人民币汇率中间价（月初，月末）'!$K2/100 -> 4.7842 | T4: ='人民币汇率中间价（月初，月末）'!G2/100 -> 4.6987 | U4: =0.245696767189406*C4 -> 1.6723842 | V4: =0.564007693550045*C4 -> 3.8390312
B5: 期末汇率
B6: 平均汇率
B7: 46174 | C7: 美国-USD | D7: 香港-HKD | E7: 印尼-IDR | F7: 坦桑-TZS | G7: 墨西哥-MXN | H7: 越南-VND | I7: 俄罗斯-RUB | J7: 英国-GBP | K7: 泰国-THB | L7: 比利时-EUR | M7: 波兰-PLN | N7: 南非-ZAR | O7: 新加坡-SGD | P7: 菲律宾-PHP | Q7: 尼日利亚-NGN | R7: 日本-JPY | S7: 加拿大-CAD | T7: 澳大利亚-AUD | U7: 马来西亚-MYR | V7: 新西兰-NZD
B8: 期初汇率 | C8: ='人民币汇率中间价（月初，月末）'!$B4/100 -> 6.8167 | D8: ='人民币汇率中间价（月初，月末）'!$E4/100 -> 0.86986 | E8: =+E14 -> 0.00038150465 | F8: =0.000382409177820421*C8 -> 0.0026067686 | G8: =100/'人民币汇率中间价（月初，月末）'!$Y4 -> 0.39212611 | H8: =0.0000379830975215987*C8 -> 0.00025891938 | I8: =100/'人民币汇率中间价（月初，月末）'!$N4 -> 0.095339791 | J8: ='人民币汇率中间价（月初，月末）'!$F4/100 -> 9.1339 | K8: =100/'人民币汇率中间价（月初，月末）'!$Z4 -> 0.2082856 | L8: ='人民币汇率中间价（月初，月末）'!$C4/100 -> 7.9122 | M8: =100/'人民币汇率中间价（月初，月末）'!$T4 -> 1.8726241 | N8: =100/'人民币汇率中间价（月初，月末）'!$O4 -> 0.41827004 | O8: ='人民币汇率中间价（月初，月末）'!$I4/100 -> 5.3197 | P8: =0.0162716718327073*C8 -> 0.11091911 | Q8: =0.000727902693968077*C8 -> 0.0049618943 | R8: ='人民币汇率中间价（月初，月末）'!$D4/100 -> 0.042656 | S8: ='人民币汇率中间价（月初，月末）'!$K4/100 -> 4.9188 | T8: ='人民币汇率中间价（月初，月末）'!G4/100 -> 4.8759 | U8: =0.251051215709286*C8 -> 1.7113408 | V8: =0.591909176249707*C8 -> 4.0348673
B9: 期末汇率 | C9: ='人民币汇率中间价（月初，月末）'!$B3/100 -> 6.8109 | D9: ='人民币汇率中间价（月初，月末）'!$E3/100 -> 0.86855 | E9: =+'印尼央行汇率-7月'!O361 -> 0.00038044078 | F9: =0.000380952380952127*C9 -> 0.0025946286 | G9: =100/'人民币汇率中间价（月初，月末）'!$Y3 -> 0.38968124 | H9: =0.0000380372765309995*C9 -> 0.00025906809 | I9: =100/'人民币汇率中间价（月初，月末）'!$N3 -> 0.088266707 | J9: ='人民币汇率中间价（月初，月末）'!$F3/100 -> 9.0145 | K9: =100/'人民币汇率中间价（月初，月末）'!$Z3 -> 0.20424419 | L9: ='人民币汇率中间价（月初，月末）'!$C3/100 -> 7.7671 | M9: =100/'人民币汇率中间价（月初，月末）'!$T3 -> 1.8121195 | N9: =100/'人民币汇率中间价（月初，月末）'!$O3 -> 0.41440471 | O9: ='人民币汇率中间价（月初，月末）'!$I3/100 -> 5.2605 | P9: =0.0163221336297023*C9 -> 0.11116842 | Q9: =0.00072393997089663*C9 -> 0.0049306827 | R9: ='人民币汇率中间价（月初，月末）'!$D3/100 -> 0.042045 | S9: ='人民币汇率中间价（月初，月末）'!$K3/100 -> 4.7847 | T9: ='人民币汇率中间价（月初，月末）'!G3/100 -> 4.6804 | U9: =0.245696767189406*C9 -> 1.6734161 | V9: =0.564007693550045*C9 -> 3.8414
B10: 平均汇率 | C10: =+美元!IF2 -> 6.8153762 | D10: =+港币!IC2 -> 0.86961762 | E10: =+印尼盾!UM2 -> 0.00038168549 | F10: =+坦桑!MB2 -> 0.0025963338 | G10: =+墨西哥比索!LA2 -> 0.39160036 | H10: =+越南盾!LJ2 -> 0.00025923835 | I10: =+俄罗斯卢布!KB2 -> 0.092215031 | J10: =+英镑!KZ2 -> 9.066181 | K10: =+泰国泰铢!JO2 -> 0.20641072 | L10: =+'欧元 '!KV2 -> 7.8310619 | M10: =+兹罗提!HX2 -> 1.8422135 | N10: =+南非兰特!GK2 -> 0.41486234 | O10: =+新加坡!FL2 -> 5.2798714 | P10: =+菲律宾!GT2 -> 0.11124148 | Q10: =+尼日利亚!DG2 -> 0.0049339232 | R10: =+日元!IZ2 -> 0.042350574 | S10: =+加元!CW2 -> 4.845681 | T10: =+澳元!KA2 -> 4.7786048 | U10: =+马来西亚!BE2 -> 1.6745159 | V10: =+新西兰!AM2 -> 3.8439246
B11: 46143 | C11: 美国-USD | D11: 香港-HKD | E11: 印尼-IDR | F11: 坦桑-TZS | G11: 墨西哥-MXN | H11: 越南-VND | I11: 俄罗斯-RUB | J11: 英国-GBP | K11: 泰国-THB | L11: 比利时-EUR | M11: 波兰-PLN | N11: 南非-ZAR | O11: 新加坡-SGD | P11: 菲律宾-PHP | Q11: 尼日利亚-NGN | R11: 日本-JPY | S11: 加拿大-CAD | T11: 澳大利亚-AUD | U11: 马来西亚-MYR | V11: 新西兰-NZD
B12: 46143 | C12: 6.8628 | D12: 0.87581 | E12: 0.00039428756 | F12: 0.0026446243 | G12: 0.3910833 | H12: 0.00026038853 | I12: 0.091435259 | J12: 9.2416 | K12: 0.20891219 | L12: 8.0057 | M12: 1.880194 | N12: 0.40738176 | O12: 5.3518 | P12: 0.11128444 | Q12: 0.0049870288 | R12: 0.042812 | S12: 5.0085 | T12: 4.8824 | U12: 1.7326518 | V12: 4
B13: 46148 | C13: ='人民币汇率中间价（月初，月末）'!$B6/100 -> 6.8562 | D13: ='人民币汇率中间价（月初，月末）'!$E6/100 -> 0.87504 | E13: =+'印尼央行汇率-7月'!O339 -> 0.00039198009 | F13: =0.00038535645472082*C13 -> 0.0026420809 | G13: =100/'人民币汇率中间价（月初，月末）'!$Y6 -> 0.39471087 | H13: =0.0000379420245864298*C13 -> 0.00026013811 | I13: =100/'人民币汇率中间价（月初，月末）'!$N6 -> 0.090413461 | J13: ='人民币汇率中间价（月初，月末）'!$F6/100 -> 9.2712 | K13: =100/'人民币汇率中间价（月初，月末）'!$Z6 -> 0.21039344 | L13: ='人民币汇率中间价（月初，月末）'!$C6/100 -> 8.0094 | M13: =100/'人民币汇率中间价（月初，月末）'!$T6 -> 1.8887168 | N13: =100/'人民币汇率中间价（月初，月末）'!$O6 -> 0.41232013 | O13: ='人民币汇率中间价（月初，月末）'!$I6/100 -> 5.3677 | P13: =0.0162156026526111*C13 -> 0.11117741 | Q13: =0.000726675532109729*C13 -> 0.0049822328 | R13: ='人民币汇率中间价（月初，月末）'!$D6/100 -> 0.043338 | S13: ='人民币汇率中间价（月初，月末）'!$K6/100 -> 5.0224 | T13: ='人民币汇率中间价（月初，月末）'!G6/100 -> 4.9245 | U13: =0.252470103108942*C13 -> 1.7309855 | V13: =0.582852480037303*C13 -> 3.9961532
B14: 期末汇率 | C14: ='人民币汇率中间价（月初，月末）'!$B5/100 -> 6.8176 | D14: ='人民币汇率中间价（月初，月末）'!$E5/100 -> 0.87029 | E14: =+'印尼央行汇率-7月'!O348 -> 0.00038150465 | F14: =0.000382409177820421*C14 -> 0.0026071128 | G14: =100/'人民币汇率中间价（月初，月末）'!$Y5 -> 0.39312812 | H14: =0.0000379830975215987*C14 -> 0.00025895357 | I14: =100/'人民币汇率中间价（月初，月末）'!$N5 -> 0.095506423 | J14: ='人民币汇率中间价（月初，月末）'!$F5/100 -> 9.1335 | K14: =100/'人民币汇率中间价（月初，月末）'!$Z5 -> 0.20825524 | L14: ='人民币汇率中间价（月初，月末）'!$C5/100 -> 7.916 | M14: =100/'人民币汇率中间价（月初，月末）'!$T5 -> 1.8751524 | N14: =100/'人民币汇率中间价（月初，月末）'!$O5 -> 0.4189008 | O14: ='人民币汇率中间价（月初，月末）'!$I5/100 -> 5.3271 | P14: =0.0162716718327073*C14 -> 0.11093375 | Q14: =0.000727902693968077*C14 -> 0.0049625494 | R14: ='人民币汇率中间价（月初，月末）'!$D5/100 -> 0.042718 | S14: ='人民币汇率中间价（月初，月末）'!$K5/100 -> 4.9257 | T14: ='人民币汇率中间价（月初，月末）'!G5/100 -> 4.8641 | U14: =0.251051215709286*C14 -> 1.7115668 | V14: =0.591909176249707*C14 -> 4.0354
B15: 平均汇率 | C15: =+美元!IB2 -> 6.8385167 | D15: =+港币!HY2 -> 0.87309722 | E15: =+印尼盾!UG2 -> 0.00038442389 | F15: =+坦桑!LV2 -> 0.0026151115 | G15: =+墨西哥比索!KV2 -> 0.39511116 | H15: =+越南盾!LD2 -> 0.00025974805 | I15: =+俄罗斯卢布!JW2 -> 0.093484834 | J15: =+英镑!KU2 -> 9.1926833 | K15: =+泰国泰铢!JJ2 -> 0.20958429 | L15: =+'欧元 '!KQ2 -> 7.9606389 | M15: =+兹罗提!HS2 -> 1.879711 | N15: =+南非兰特!GF2 -> 0.41449918 | O15: =+新加坡!FG2 -> 5.3488167 | P15: =+菲律宾!GN2 -> 0.1112741 | Q15: =+尼日利亚!DA2 -> 0.0049777747 | R15: =+日元!IU2 -> 0.0431168 | S15: =+加元!CQ2 -> 4.9627222 | T15: =+澳元!JV2 -> 4.8992778 | U15: =+马来西亚!AY2 -> 1.7168179 | V15: =+新西兰!AG2 -> 4.0477808
B16: 46113 | C16: 美国-USD | D16: 香港-HKD | E16: 印尼-IDR | F16: 坦桑-TZS | G16: 墨西哥-MXN | H16: 越南-VND | I16: 俄罗斯-RUB | J16: 英国-GBP | K16: 泰国-THB | L16: 比利时-EUR | M16: 波兰-PLN | N16: 南非-ZAR | O16: 新加坡-SGD | P16: 菲律宾-PHP | Q16: 尼日利亚-NGN | R16: 日本-JPY | S16: 加拿大-CAD | T16: 澳大利亚-AUD | U16: 马来西亚-MYR | V16: 新西兰-NZD
B17: 期初汇率 | C17: ='人民币汇率中间价（月初，月末）'!$B8/100 -> 6.9025 | D17: ='人民币汇率中间价（月初，月末）'!$E8/100 -> 0.88065 | E17: 0.00040630752 | F17: 0.0026702128 | G17: =100/'人民币汇率中间价（月初，月末）'!$Y8 -> 0.38529706 | H17: 0.00026200418 | I17: =100/'人民币汇率中间价（月初，月末）'!$N8 -> 0.084786 | J17: ='人民币汇率中间价（月初，月末）'!$F8/100 -> 9.133 | K17: =100/'人民币汇率中间价（月初，月末）'!$Z8 -> 0.21178813 | L17: ='人民币汇率中间价（月初，月末）'!$C8/100 -> 7.9806 | M17: =100/'人民币汇率中间价（月初，月末）'!$T8 -> 1.8609498 | N17: =100/'人民币汇率中间价（月初，月末）'!$O8 -> 0.40841331 | O17: ='人民币汇率中间价（月初，月末）'!$I8/100 -> 5.3726 | P17: 0.11388103 | Q17: 0.0049859145 | R17: ='人民币汇率中间价（月初，月末）'!$D8/100 -> 0.04346 | S17: ='人民币汇率中间价（月初，月末）'!$K8/100 -> 4.9582 | T17: ='人民币汇率中间价（月初，月末）'!G8/100 -> 4.7649 | U17: 1.7114581 | V17: 3.9461383
B18: 期末汇率 | C18: ='人民币汇率中间价（月初，月末）'!$B7/100 -> 6.8628 | D18: ='人民币汇率中间价（月初，月末）'!$E7/100 -> 0.87581 | E18: =+'印尼央行汇率-7月'!O330 -> 0.00039428756 | F18: =0.00038535645472082*C18 -> 0.0026446243 | G18: =100/'人民币汇率中间价（月初，月末）'!$Y7 -> 0.3910833 | H18: =0.0000379420245864298*C18 -> 0.00026038853 | I18: =100/'人民币汇率中间价（月初，月末）'!$N7 -> 0.091435259 | J18: ='人民币汇率中间价（月初，月末）'!$F7/100 -> 9.2416 | K18: =100/'人民币汇率中间价（月初，月末）'!$Z7 -> 0.20891219 | L18: ='人民币汇率中间价（月初，月末）'!$C7/100 -> 8.0057 | M18: =100/'人民币汇率中间价（月初，月末）'!$T7 -> 1.880194 | N18: =100/'人民币汇率中间价（月初，月末）'!$O7 -> 0.40738176 | O18: ='人民币汇率中间价（月初，月末）'!$I7/100 -> 5.3518 | P18: =0.0162156026526111*C18 -> 0.11128444 | Q18: =0.000726675532109729*C18 -> 0.0049870288 | R18: ='人民币汇率中间价（月初，月末）'!$D7/100 -> 0.042812 | S18: ='人民币汇率中间价（月初，月末）'!$K7/100 -> 5.0085 | T18: ='人民币汇率中间价（月初，月末）'!G7/100 -> 4.8824 | U18: =0.252470103108942*C18 -> 1.7326518 | V18: =0.582852480037303*C18 -> 4
B19: 平均汇率 | C19: =+美元!HX2 -> 6.8683143 | D19: =港币!HU2 -> 0.87675143 | E19: =+印尼盾!UA2 -> 0.00039646238 | F19: =+坦桑!LP2 -> 0.0026467492 | G19: =+墨西哥比索!KQ2 -> 0.39287291 | H19: =+越南盾!KX2 -> 0.00026059775 | I19: =+俄罗斯卢布!JR2 -> 0.089070045 | J19: =+英镑!KP2 -> 9.213281 | K19: =+泰国泰铢!JE2 -> 0.21202013 | L19: =+'欧元 '!KL2 -> 8.0140714 | M19: =+兹罗提!HN2 -> 1.8865348 | N19: =+南非兰特!GA2 -> 0.41394971 | O19: =+新加坡!FB2 -> 5.3693857 | P19: =+菲律宾!GH2 -> 0.11137386 | Q19: =+尼日利亚!CU2 -> 0.0049910359 | R19: =+日元!IP2 -> 0.043057215 | S19: =+加元!CK2 -> 4.9777286 | T19: =+澳元!JQ2 -> 4.8557381 | U19: =+马来西亚!AS2 -> 1.734044 | V19: =+新西兰!AA2 -> 4.003214
B20: 46082 | C20: 美国-USD | D20: 香港-HKD | E20: 印尼-IDR | F20: 坦桑-TZS | G20: 墨西哥-MXN | H20: 越南-VND | I20: 俄罗斯-RUB | J20: 英国-GBP | K20: 泰国-THB | L20: 比利时-EUR | M20: 波兰-PLN | N20: 南非-ZAR | O20: 新加坡-SGD | P20: 菲律宾-PHP | Q20: 尼日利亚-NGN | R20: 日本-JPY | S20: 加拿大-CAD | T20: 澳大利亚-AUD | U20: 马来西亚-MYR | V20: 新西兰-NZD
B21: 46082 | C21: 6.9228 | D21: 0.88484 | E21: 0.00040806666 | F21: 0.0027095108 | G21: 0.40117142 | H21: 0.00026549569 | I21: 0.089053539 | J21: 9.2709 | K21: 0.22089196 | L21: 8.1208 | M21: 1.9268194 | N21: 0.43245113 | O21: 5.4488 | P21: 0.11996881 | Q21: 0.0051147774 | R21: 0.044216 | S21: 5.0266 | T21: 4.8776 | U21: 1.7732697 | V21: 4.1018
B22: 46083 | C22: ='人民币汇率中间价（月初，月末）'!$B10/100 -> 6.9236 | D22: ='人民币汇率中间价（月初，月末）'!$E10/100 -> 0.88518 | E22: ='印尼央行汇率-7月'!O301 -> 0.00040853178 | F22: =0.000391389432485631*C22 -> 0.0027098239 | G22: =100/'人民币汇率中间价（月初，月末）'!$Y10 -> 0.39899453 | H22: =0.0000383509108341314*C22 -> 0.00026552637 | I22: =100/'人民币汇率中间价（月初，月末）'!$N10 -> 0.089110675 | J22: ='人民币汇率中间价（月初，月末）'!$F10/100 -> 9.2493 | K22: =100/'人民币汇率中间价（月初，月末）'!$Z10 -> 0.22078954 | L22: ='人民币汇率中间价（月初，月末）'!$C10/100 -> 8.1135 | M22: =100/'人民币汇率中间价（月初，月末）'!$T10 -> 1.9217834 | N22: =100/'人民币汇率中间价（月初，月末）'!$O10 -> 0.42942414 | O22: ='人民币汇率中间价（月初，月末）'!$I10/100 -> 5.4378 | P22: =0.017329520838063*C22 -> 0.11998267 | Q22: =0.000738830726493669*C22 -> 0.0051153684 | R22: ='人民币汇率中间价（月初，月末）'!$D10/100 -> 0.044123 | S22: ='人民币汇率中间价（月初，月末）'!$K10/100 -> 5.0439 | T22: ='人民币汇率中间价（月初，月末）'!G10/100 -> 4.8724 | U22: =0.256149207265694*C22 -> 1.7734747 | V22: =0.592505922459121*C22 -> 4.102274
B23: 期末汇率 | C23: ='人民币汇率中间价（月初，月末）'!$B9/100 -> 6.9194 | D23: ='人民币汇率中间价（月初，月末）'!$E9/100 -> 0.88295 | E23: =+'印尼央行汇率-7月'!O311 -> 0.00040672892 | F23: =0.000386847195357504*C23 -> 0.0026767505 | G23: =100/'人民币汇率中间价（月初，月末）'!$Y9 -> 0.3814319 | H23: =0.0000379578667678839*C23 -> 0.00026264566 | I23: =100/'人民币汇率中间价（月初，月末）'!$N9 -> 0.08510421 | J23: ='人民币汇率中间价（月初，月末）'!$F9/100 -> 9.1169 | K23: =100/'人民币汇率中间价（月初，月末）'!$Z9 -> 0.21069487 | L23: ='人民币汇率中间价（月初，月末）'!$C9/100 -> 7.9302 | M23: =100/'人民币汇率中间价（月初，月末）'!$T9 -> 1.8479165 | N23: =100/'人民币汇率中间价（月初，月末）'!$O9 -> 0.40228498 | O23: ='人民币汇率中间价（月初，月末）'!$I9/100 -> 5.3575 | P23: =0.0164985192582434*C23 -> 0.11415985 | Q23: =0.000722334585378704*C23 -> 0.0049981219 | R23: ='人民币汇率中间价（月初，月末）'!$D9/100 -> 0.043296 | S23: ='人民币汇率中间价（月初，月末）'!$K9/100 -> 4.9684 | T23: ='人民币汇率中间价（月初，月末）'!G9/100 -> 4.7382 | U23: =0.247947571946103*C23 -> 1.7156484 | V23: =0.571696967945197*C23 -> 3.9558
B24: 平均汇率 | C24: =美元!HT2 -> 6.9036909 | D24: =港币!HQ2 -> 0.88215682 | E24: =印尼盾!TU2 -> 0.00040830841 | F24: =坦桑!LJ2 -> 0.0026706735 | G24: =墨西哥比索!KL2 -> 0.38856557 | H24: =越南盾!KR2 -> 0.00026204938 | I24: =俄罗斯卢布!JM2 -> 0.085816251 | J24: =英镑!KK2 -> 9.2105227 | K24: =泰国泰铢!IZ2 -> 0.21410838 | L24: ='欧元 '!KG2 -> 7.9806818 | M24: =兹罗提!HI2 -> 1.8701074 | N24: =南非兰特!FV2 -> 0.41290361 | O24: =新加坡!EW2 -> 5.3939409 | P24: =菲律宾!GB2 -> 0.11390068 | Q24: =尼日利亚!CO2 -> 0.0049867747 | R24: =日元!IK2 -> 0.043506355 | S24: =加元!CE2 -> 5.0326727 | T24: =澳元!JL2 -> 4.8449227 | U24: =马来西亚!AM2 -> 1.7117534 | V24: =新西兰!U2 -> 3.9468192
B25: 46054 | C25: 美国-USD | D25: 香港-HKD | E25: 印尼-IDR | F25: 坦桑-TZS | G25: 墨西哥-MXN | H25: 越南-VND | I25: 俄罗斯-RUB | J25: 英国-GBP | K25: 泰国-THB | L25: 比利时-EUR | M25: 波兰-PLN | N25: 南非-ZAR | O25: 新加坡-SGD | P25: 菲律宾-PHP | Q25: 尼日利亚-NGN | R25: 日本-JPY | S25: 加拿大-CAD | T25: 澳大利亚-AUD | U25: 马来西亚-MYR | V25: 新西兰-NZD
B26: 46054 | C26: 6.9678 | D26: 0.89262 | E26: 0.00041385418 | F26: 0.0027164912 | G26: 0.40451438 | H26: 0.00026799231 | I26: 0.092364248 | J26: 9.608 | K26: 0.22239025 | L26: 8.3244 | M26: 1.9809826 | N26: 0.44263456 | O26: 5.5061 | P26: 0.11810131 | Q26: 0.0050146096 | R26: 0.045464 | S26: 5.1577 | T26: 4.9019 | U26: 1.7727353 | V26: 4.2233
B27: 46055 | C27: ='人民币汇率中间价（月初，月末）'!$B12/100 -> 6.9695 | D27: ='人民币汇率中间价（月初，月末）'!$E12/100 -> 0.89249 | E27: =+'印尼央行汇率-7月'!O281 -> 0.00041371036 | F27: =0.000389863547758529*C27 -> 0.002717154 | G27: =100/'人民币汇率中间价（月初，月末）'!$Y12 -> 0.39909007 | H27: =0.0000384615384615343*C27 -> 0.00026805769 | I27: =100/'人民币汇率中间价（月初，月末）'!$N12 -> 0.091544074 | J27: ='人民币汇率中间价（月初，月末）'!$F12/100 -> 9.5385 | K27: =100/'人民币汇率中间价（月初，月末）'!$Z12 -> 0.22094565 | L27: ='人民币汇率中间价（月初，月末）'!$C12/100 -> 8.2651 | M27: =100/'人民币汇率中间价（月初，月末）'!$T12 -> 1.9620154 | N27: =100/'人民币汇率中间价（月初，月末）'!$O12 -> 0.43053343 | O27: ='人民币汇率中间价（月初，月末）'!$I12/100 -> 5.4759 | P27: =0.0169495834638366*C27 -> 0.11813012 | Q27: =0.000719683339332442*C27 -> 0.005015833 | R27: ='人民币汇率中间价（月初，月末）'!$D12/100 -> 0.044926 | S27: ='人民币汇率中间价（月初，月末）'!$K12/100 -> 5.1098 | T27: ='人民币汇率中间价（月初，月末）'!G12/100 -> 4.843 | U27: =0.254418228223419*C27 -> 1.7731678 | V27: =0.60611670828669*C27 -> 4.2243304
B28: 期末汇率 | C28: ='人民币汇率中间价（月初，月末）'!$B11/100 -> 6.9228 | D28: ='人民币汇率中间价（月初，月末）'!$E11/100 -> 0.88484 | E28: =+'印尼央行汇率-7月'!O291 -> 0.00040806666 | F28: =0.000391389432485631*C28 -> 0.0027095108 | G28: =100/'人民币汇率中间价（月初，月末）'!$Y11 -> 0.40117142 | H28: =0.0000383509108341314*C28 -> 0.00026549569 | I28: =100/'人民币汇率中间价（月初，月末）'!$N11 -> 0.089053539 | J28: ='人民币汇率中间价（月初，月末）'!$F11/100 -> 9.2709 | K28: =100/'人民币汇率中间价（月初，月末）'!$Z11 -> 0.22089196 | L28: ='人民币汇率中间价（月初，月末）'!$C11/100 -> 8.1208 | M28: =100/'人民币汇率中间价（月初，月末）'!$T11 -> 1.9268194 | N28: =100/'人民币汇率中间价（月初，月末）'!$O11 -> 0.43245113 | O28: ='人民币汇率中间价（月初，月末）'!$I11/100 -> 5.4488 | P28: =0.017329520838063*C28 -> 0.11996881 | Q28: =0.000738830726493669*C28 -> 0.0051147774 | R28: ='人民币汇率中间价（月初，月末）'!$D11/100 -> 0.044216 | S28: ='人民币汇率中间价（月初，月末）'!$K11/100 -> 5.0266 | T28: ='人民币汇率中间价（月初，月末）'!G11/100 -> 4.8776 | U28: =0.256149207265694*C28 -> 1.7732697 | V28: =0.592505922459121*C28 -> 4.1018
B29: 平均汇率 | C29: =+美元!HP2 -> 6.94615 | D29: =+港币!HM2 -> 0.88875357 | E29: =+印尼盾!TO2 -> 0.00041449755 | F29: =+坦桑!LD2 -> 0.0027186497 | G29: =+墨西哥比索!KG2 -> 0.40178623 | H29: =+越南盾!KL2 -> 0.00026639118 | I29: =+俄罗斯卢布!JH2 -> 0.090005471 | J29: =+英镑!KF2 -> 9.4255714 | K29: =+泰国泰铢!IU2 -> 0.22109848 | L29: =+'欧元 '!KB2 -> 8.2003286 | M29: =+兹罗提!HD2 -> 1.9455091 | N29: =+南非兰特!FQ2 -> 0.43336676 | O29: =+新加坡!ER2 -> 5.4691857 | P29: =+菲律宾!FV2 -> 0.12037345 | Q29: =+尼日利亚!CI2 -> 0.0051320291 | R29: =+日元!IF2 -> 0.044610239 | S29: =+加元!BY2 -> 5.0785929 | T29: =+澳元!JG2 -> 4.8785 | U29: =+马来西亚!AG2 -> 1.7792508 | V29: =+新西兰!O2 -> 4.115635
B30: 46023 | C30: 美国-USD | D30: 香港-HKD | E30: 印尼-IDR | F30: 坦桑-TZS | G30: 墨西哥-MXN | H30: 越南-VND | I30: 俄罗斯-RUB | J30: 英国-GBP | K30: 泰国-THB | L30: 比利时-EUR | M30: 波兰-PLN | N30: 南非-ZAR | O30: 新加坡-SGD | P30: 菲律宾-PHP | Q30: 尼日利亚-NGN | R30: 日本-JPY | S30: 加拿大-CAD | T30: 澳大利亚-AUD | U30: 马来西亚-MYR | V30: 新西兰-NZD
B31: 期初汇率 | C31: ='人民币汇率中间价（月初，月末）'!$B14/100 -> 7.023 | D31: ='人民币汇率中间价（月初，月末）'!$E14/100 -> 0.90141 | E31: =+'印尼央行汇率-7月'!O262 -> 0.0004181581 | F31: =0.000404858299594806*C31 -> 0.0028433198 | G31: =100/'人民币汇率中间价（月初，月末）'!$Y14 -> 0.39128223 | H31: =0.0000380734818199161*C31 -> 0.00026739006 | I31: =100/'人民币汇率中间价（月初，月末）'!$N14 -> 0.087014027 | J31: ='人民币汇率中间价（月初，月末）'!$F14/100 -> 9.4168 | K31: =100/'人民币汇率中间价（月初，月末）'!$Z14 -> 0.22218272 | L31: ='人民币汇率中间价（月初，月末）'!$C14/100 -> 8.2027 | M31: =100/'人民币汇率中间价（月初，月末）'!$T14 -> 1.9481025 | N31: =100/'人民币汇率中间价（月初，月末）'!$O14 -> 0.42482688 | O31: ='人民币汇率中间价（月初，月末）'!$I14/100 -> 5.4428 | P31: =0.0170014536249532*C31 -> 0.11940121 | Q31: =0.000687365534116197*C31 -> 0.0048273681 | R31: ='人民币汇率中间价（月初，月末）'!$D14/100 -> 0.04466 | S31: ='人民币汇率中间价（月初，月末）'!$K14/100 -> 5.0945 | T31: ='人民币汇率中间价（月初，月末）'!G14/100 -> 4.6817 | U31: =0.246405022669518*C31 -> 1.7305025 | V31: =0.576485317550649*C31 -> 4.0486564
B32: 期末汇率 | C32: ='人民币汇率中间价（月初，月末）'!$B13/100 -> 6.9678 | D32: ='人民币汇率中间价（月初，月末）'!$E13/100 -> 0.89262 | E32: =+'印尼央行汇率-7月'!O271 -> 0.00041385418 | F32: =0.000389863547758529*C32 -> 0.0027164912 | G32: =100/'人民币汇率中间价（月初，月末）'!$Y13 -> 0.40451438 | H32: =0.0000384615384615343*C32 -> 0.00026799231 | I32: =100/'人民币汇率中间价（月初，月末）'!$N13 -> 0.092364248 | J32: ='人民币汇率中间价（月初，月末）'!$F13/100 -> 9.608 | K32: =100/'人民币汇率中间价（月初，月末）'!$Z13 -> 0.22239025 | L32: ='人民币汇率中间价（月初，月末）'!$C13/100 -> 8.3244 | M32: =100/'人民币汇率中间价（月初，月末）'!$T13 -> 1.9809826 | N32: =100/'人民币汇率中间价（月初，月末）'!$O13 -> 0.44263456 | O32: ='人民币汇率中间价（月初，月末）'!$I13/100 -> 5.5061 | P32: =0.0169495834638366*C32 -> 0.11810131 | Q32: =0.000719683339332442*C32 -> 0.0050146096 | R32: ='人民币汇率中间价（月初，月末）'!$D13/100 -> 0.045464 | S32: ='人民币汇率中间价（月初，月末）'!$K13/100 -> 5.1577 | T32: ='人民币汇率中间价（月初，月末）'!G13/100 -> 4.9019 | U32: =0.254418228223419*C32 -> 1.7727353 | V32: =0.60611670828669*C32 -> 4.2233
B33: 平均汇率 | C33: =+美元!HL2 -> 7.00156 | D33: =港币!HI2 -> 0.898127 | E33: =印尼盾!TI2 -> 0.00041710711 | F33: =坦桑!KX2 -> 0.002729653 | G33: =墨西哥比索!KB2 -> 0.39574338 | H33: =越南盾!KF2 -> 0.00026929077 | I33: =俄罗斯卢布!JC2 -> 0.089235679 | J33: =英镑!KA2 -> 9.434105 | K33: =泰国泰铢!IP2 -> 0.22304899 | L33: ='欧元 '!JW2 -> 8.192485 | M33: =兹罗提!GY2 -> 1.9453115 | N33: =南非兰特!FL2 -> 0.42929694 | O33: =新加坡!EM2 -> 5.45299 | P33: =菲律宾!FP2 -> 0.11867353 | Q33: =尼日利亚!CC2 -> 0.0050389061 | R33: =日元!IA2 -> 0.044531733 | S33: =加元!BS2 -> 5.058775 | T33: =澳元!JB2 -> 4.729165 | U33: =马来西亚!AA2 -> 1.7813245 | V33: =新西兰!I2 -> 4.2437625
B34: 45992 | C34: 美国-USD | D34: 香港-HKD | E34: 印尼-IDR | F34: 坦桑-TZS | G34: 墨西哥-MXN | H34: 越南-VND | I34: 俄罗斯-RUB | J34: 英国-GBP | K34: 泰国-THB | L34: 比利时-EUR | M34: 波兰-PLN | N34: 南非-ZAR | O34: 新加坡-SGD | P34: 菲律宾-PHP | Q34: 尼日利亚-NGN | R34: 日本-JPY | S34: 加拿大-CAD | T34: 澳大利亚-AUD | U34: 马来西亚-MYR | V34: 新西兰-NZD
B35: 期初汇率 | C35: ='人民币汇率中间价（月初，月末）'!$B16/100 -> 7.0759 | D35: ='人民币汇率中间价（月初，月末）'!$E16/100 -> 0.90877 | E35: =+'印尼央行汇率-7月'!O242 -> 0.00042482147 | F35: =0.000406091370558754*C35 -> 0.0028734619 | G35: =100/'人民币汇率中间价（月初，月末）'!$Y16 -> 0.38678734 | H35: =0.0000379139731948208*C35 -> 0.00026827548 | I35: =100/'人民币汇率中间价（月初，月末）'!$N16 -> 0.091256696 | J35: ='人民币汇率中间价（月初，月末）'!$F16/100 -> 9.3616 | K35: =100/'人民币汇率中间价（月初，月末）'!$Z16 -> 0.22010917 | L35: ='人民币汇率中间价（月初，月末）'!$C16/100 -> 8.2052 | M35: =100/'人民币汇率中间价（月初，月末）'!$T16 -> 1.9374588 | N35: =100/'人民币汇率中间价（月初，月末）'!$O16 -> 0.41324022 | O35: ='人民币汇率中间价（月初，月末）'!$I16/100 -> 5.4569 | P35: =0.0170169318477886*C35 -> 0.12041011 | Q35: =0.000691412313360252*C35 -> 0.0048923644 | R35: ='人民币汇率中间价（月初，月末）'!$D16/100 -> 0.045331 | S35: ='人民币汇率中间价（月初，月末）'!$K16/100 -> 5.0621 | T35: ='人民币汇率中间价（月初，月末）'!G16/100 -> 4.6302 | U35: =0.24212410151402*C35 -> 1.7132459 | V35: =0.572588961561825*C35 -> 4.0515822
B36: 期末汇率 | C36: ='人民币汇率中间价（月初，月末）'!$B15/100 -> 7.0288 | D36: ='人民币汇率中间价（月初，月末）'!$E15/100 -> 0.90322 | E36: =+'印尼央行汇率-7月'!O253 -> 0.00041655038 | F36: =0.000404858299594806*C36 -> 0.002845668 | G36: =100/'人民币汇率中间价（月初，月末）'!$Y15 -> 0.38987875 | H36: =0.0000380734818199161*C36 -> 0.00026761089 | I36: =100/'人民币汇率中间价（月初，月末）'!$N15 -> 0.088052973 | J36: ='人民币汇率中间价（月初，月末）'!$F15/100 -> 9.4346 | K36: =100/'人民币汇率中间价（月初，月末）'!$Z15 -> 0.22251891 | L36: ='人民币汇率中间价（月初，月末）'!$C15/100 -> 8.2355 | M36: =100/'人民币汇率中间价（月初，月末）'!$T15 -> 1.9497358 | N36: =100/'人民币汇率中间价（月初，月末）'!$O15 -> 0.42244001 | O36: ='人民币汇率中间价（月初，月末）'!$I15/100 -> 5.4586 | P36: =0.0170014536249532*C36 -> 0.11949982 | Q36: =0.000687365534116197*C36 -> 0.0048313549 | R36: ='人民币汇率中间价（月初，月末）'!$D15/100 -> 0.044797 | S36: ='人民币汇率中间价（月初，月末）'!$K15/100 -> 5.1142 | T36: ='人民币汇率中间价（月初，月末）'!G15/100 -> 4.6892 | U36: =0.246405022669518*C36 -> 1.7319316 | V36: =0.576485317550649*C36 -> 4.052
B37: 平均汇率 | C37: =+美元!HH2 -> 7.0593478 | D37: =+港币!HE2 -> 0.90731696 | E37: =+印尼盾!TC2 -> 0.00042064997 | F37: =+坦桑!KR2 -> 0.0028580356 | G37: =+墨西哥比索!JW2 -> 0.39005066 | H37: =+越南盾!JZ2 -> 0.00026877395 | I37: =+俄罗斯卢布!IX2 -> 0.089839469 | J37: =+英镑!JV2 -> 9.4345348 | K37: =+泰国泰铢!IK2 -> 0.22313091 | L37: =+'欧元 '!JR2 -> 8.256787 | M37: =+兹罗提!GT2 -> 1.9553683 | N37: =+南非兰特!FG2 -> 0.41854329 | O37: =+新加坡!EH2 -> 5.4619522 | P37: =+菲律宾!FJ2 -> 0.12001917 | Q37: =+尼日利亚!BW2 -> 0.0048523524 | R37: =+日元!HV2 -> 0.04521643 | S37: =+加元!BM2 -> 5.1073435 | T37: =+澳元!IW2 -> 4.6802783 | U37: =+马来西亚!U2 -> 1.7394588 | V37: =+新西兰!C2 -> 4.0696104
B38: 45986 | C38: 美国-USD | D38: 香港-HKD | E38: 印尼-IDR | F38: 坦桑-TZS | G38: 墨西哥-MXN | H38: 越南-VND | I38: 俄罗斯-RUB | J38: 英国-GBP | K38: 泰国-THB | L38: 比利时-EUR | M38: 波兰-PLN | N38: 南非-ZAR | O38: 新加坡-SGD | P38: 菲律宾-PHP | Q38: 尼日利亚-NGN | R38: 日本-JPY | S38: 加拿大-CAD | T38: 澳大利亚-AUD | U38: 马来西亚-MYR
B39: 期初汇率 | C39: ='人民币汇率中间价（月初，月末）'!$B18/100 -> 7.0867 | D39: ='人民币汇率中间价（月初，月末）'!$E18/100 -> 0.91175 | E39: =+'印尼央行汇率-7月'!O224 -> 0.00042788803 | F39: =0.000406504065040592*C39 -> 0.0028807724 | G39: =100/'人民币汇率中间价（月初，月末）'!$Y18 -> 0.38235069 | H39: =0.0000379794910748178*C39 -> 0.00026914926 | I39: =100/'人民币汇率中间价（月初，月末）'!$N18 -> 0.088394664 | J39: ='人民币汇率中间价（月初，月末）'!$F18/100 -> 9.3264 | K39: =100/'人民币汇率中间价（月初，月末）'!$Z18 -> 0.21923094 | L39: ='人民币汇率中间价（月初，月末）'!$C18/100 -> 8.1845 | M39: =100/'人民币汇率中间价（月初，月末）'!$T18 -> 1.9242981 | N39: =100/'人民币汇率中间价（月初，月末）'!$O18 -> 0.40983607 | O39: ='人民币汇率中间价（月初，月末）'!$I18/100 -> 5.4545 | P39: =0.0169848495133702*C39 -> 0.12036653 | Q39: =0.000692053495733688*C39 -> 0.0049043755 | R39: ='人民币汇率中间价（月初，月末）'!$D18/100 -> 0.046083 | S39: ='人民币汇率中间价（月初，月末）'!$K18/100 -> 5.0655 | T39: ='人民币汇率中间价（月初，月末）'!G18/100 -> 4.6486 | U39: =0.23865942898536*C39 -> 1.6913078
B40: 期末汇率 | C40: ='人民币汇率中间价（月初，月末）'!$B17/100 -> 7.0789 | D40: ='人民币汇率中间价（月初，月末）'!$E17/100 -> 0.9099 | E40: =+'印尼央行汇率-7月'!O233 -> 0.00042544321 | F40: =0.000406091370558754*C40 -> 0.0028746802 | G40: =100/'人民币汇率中间价（月初，月末）'!$Y17 -> 0.38583224 | H40: =0.0000379139731948208*C40 -> 0.00026838922 | I40: =100/'人民币汇率中间价（月初，月末）'!$N17 -> 0.090797657 | J40: ='人民币汇率中间价（月初，月末）'!$F17/100 -> 9.3697 | K40: =100/'人民币汇率中间价（月初，月末）'!$Z17 -> 0.2196547 | L40: ='人民币汇率中间价（月初，月末）'!$C17/100 -> 8.2078 | M40: =100/'人民币汇率中间价（月初，月末）'!$T17 -> 1.9417476 | N40: =100/'人民币汇率中间价（月初，月末）'!$O17 -> 0.41262637 | O40: ='人民币汇率中间价（月初，月末）'!$I17/100 -> 5.4589 | P40: =0.0170169318477886*C40 -> 0.12046116 | Q40: =0.000691412313360252*C40 -> 0.0048944386 | R40: ='人民币汇率中间价（月初，月末）'!$D17/100 -> 0.045293 | S40: ='人民币汇率中间价（月初，月末）'!$K17/100 -> 5.046 | T40: ='人民币汇率中间价（月初，月末）'!G17/100 -> 4.6243 | U40: =0.24212410151402*C40 -> 1.7139723
...

Sheet 美元
A1: USD兑CNY 期末汇率 | C1: =1/C6 -> 0.15647738 | D1: =ROUND(C1,12) -> 0.15647738 | F1: USD兑CNY 期末汇率 | H1: =1/H6 -> 0.15675455 | I1: =ROUND(H1,12) -> 0.15675455 | J1: USD兑CNY | K1: 期末汇率 | L1: =L6 -> 6.3757 | O1: USD兑CNY | P1: 期末汇率 | Q1: =Q6 -> 6.3492 | T1: USD兑CNY | U1: 期末汇率 | V1: =V6 -> 6.3222 | Y1: USD兑CNY | Z1: 期末汇率 | AA1: =AA6 -> 6.3482 | AD1: USD兑CNY | AE1: 期末汇率 | AF1: =AF6 -> 6.6177 | AI1: USD兑CNY | AJ1: 期末汇率 | AK1: =AK6 -> 6.6607 | AN1: USD兑CNY | AO1: 期末汇率 | AP1: =AP6 -> 6.7114 | AS1: USD兑CNY | AT1: 期末汇率 | AU1: =AU6 -> 6.7437 | AX1: USD兑CNY | AY1: 期末汇率 | AZ1: =AZ6 -> 6.8906 | BC1: USD兑CNY | BD1: 期末汇率 | BE1: =BE6 -> 7.0998 | BH1: USD兑CNY | BI1: 期末汇率 | BJ1: =BJ6 -> 7.1768 | BM1: USD兑CNY | BN1: 期末汇率 | BO1: =BO6 -> 7.1769 | BR1: USD兑CNY | BS1: 期末汇率 | BT1: =BT6 -> 6.9646 | BV1: USD兑CNY | BW1: 期末汇率 | BX1: =BX6 -> 6.7604 | BZ1: USD兑CNY | CA1: 期末汇率 | CB1: =CB6 -> 6.9519 | CD1: USD兑CNY | CE1: 期末汇率 | CF1: =CF6 -> 6.8717 | CH1: USD兑CNY | CI1: 期末汇率 | CJ1: =CJ6 -> 6.924 | CL1: USD兑CNY | CM1: 期末汇率 | CN1: =CN6 -> 7.0821 | CP1: USD兑CNY | CQ1: 期末汇率 | CR1: =CR6 -> 7.2258 | CT1: USD兑CNY | CU1: 期末汇率 | CV1: =CV6 -> 7.1305 | CX1: USD兑CNY | CY1: 期末汇率 | CZ1: =CZ6 -> 7.1811 | DB1: USD兑CNY | DC1: 期末汇率 | DD1: =DD6 -> 7.1798 | DF1: USD兑CNY | DG1: 期末汇率 | DH1: =DH6 -> 7.1779 | DJ1: USD兑CNY | DK1: 期末汇率 | DL1: =DL6 -> 7.1018 | DN1: USD兑CNY | DO1: 期末汇率 | DP1: =DP6 -> 7.0827 | DR1: USD兑CNY | DS1: 期末汇率 | DT1: =DT6 -> 7.1055 | DV1: USD兑CNY | DW1: 期末汇率 | DX1: =DX6 -> 7.1036 | DZ1: USD兑CNY | EA1: 期末汇率 | EB1: =EB6 -> 7.095 | ED1: USD兑CNY | EE1: 期末汇率 | EF1: =EF6 -> 7.1063 | EH1: USD兑CNY | EI1: 期末汇率 | EJ1: =EJ6 -> 7.1088 | EL1: USD兑CNY | EM1: 期末汇率 | EN1: =EN6 -> 7.1268 | EP1: USD兑CNY | EQ1: 期末汇率 | ER1: =ER6 -> 7.1346 | ET1: USD兑CNY | EU1: 期末汇率 | EV1: =EV6 -> 7.1124 | EX1: USD兑CNY | EY1: 期末汇率 | EZ1: =EZ6 -> 7.0074 | FB1: USD兑CNY | FC1: 期末汇率 | FD1: =FD6 -> 7.125 | FF1: USD兑CNY | FG1: 期末汇率 | FH1: =FH6 -> 7.1877 | FJ1: USD兑CNY | FK1: 期末汇率 | FL1: =FL6 -> 7.1884 | FN1: USD兑CNY | FO1: 期末汇率 | FP1: =FP6 -> 7.1889 | FR1: USD兑CNY | FS1: 期末汇率 | FT1: =FT6 -> 7.1738 | FV1: USD兑CNY | FW1: 期末汇率 | FX1: =FX6 -> 7.1782 | FZ1: USD兑CNY | GA1: 期末汇率 | GB1: =GB6 -> 7.2014 | GD1: USD兑CNY | GE1: 期末汇率 | GF1: =GF6 -> 7.1848 | GH1: USD兑CNY | GI1: 期末汇率 | GJ1: =GJ6 -> 7.1586 | GL1: USD兑CNY | GM1: 期末汇率 | GN1: =GN6 -> 7.1494 | GP1: USD兑CNY | GQ1: 期末汇率 | GR1: =GR6 -> 7.103 | GT1: USD兑CNY | GU1: 期末汇率 | GV1: =GV6 -> 7.1055 | GX1: USD兑CNY | GY1: 期末汇率 | GZ1: =GZ6 -> 7.088 | HB1: USD兑CNY | HC1: 期末汇率 | HD1: =HD6 -> 7.0789 | HF1: USD兑CNY | HG1: 期末汇率 | HH1: =HH6 -> 7.0288 | HJ1: USD兑CNY | HK1: 期末汇率 | HL1: =HL6 -> 6.9678 | HN1: USD兑CNY | HO1: 期末汇率 | HP1: =HP6 -> 6.9228 | HR1: USD兑CNY | HS1: 期末汇率 | HT1: =HT6 -> 6.9194 | HV1: USD兑CNY | HW1: 期末汇率 | HX1: =HX6 -> 6.8628 | HZ1: USD兑CNY | IA1: 期末汇率 | IB1: =IB6 -> 6.8176 | ID1: USD兑CNY | IE1: 期末汇率 | IF1: =IF6 -> 6.8109
A2: USD兑CNY 平均汇率 | C2: =1/AVERAGE(C6:C31) -> 0.15578235 | D2: =ROUND(C2,12) -> 0.15578235 | F2: USD兑CNY 平均汇率 | H2: =1/AVERAGE(H6:H31) -> 0.15636416 | I2: =ROUND(H2,12) -> 0.15636416 | K2: 平均汇率 | L2: =AVERAGE(L6:L31) -> 6.370013 | P2: 平均汇率 | Q2: =AVERAGE(Q6:Q31) -> 6.3641286 | U2: 平均汇率 | V2: =AVERAGE(V6:V31) -> 6.3470438 | Z2: 平均汇率 | AA2: =AVERAGE(AA6:AA31) -> 6.3457217 | AE2: 平均汇率 | AF2: =AVERAGE(AF6:AF31) -> 6.4280158 | AJ2: 平均汇率 | AK2: =AVERAGE(AK6:AK31) -> 6.7071263 | AO2: 平均汇率 | AP2: =AVERAGE(AP6:AP31) -> 6.6991286 | AT2: 平均汇率 | AU2: =AVERAGE(AU6:AU31) -> 6.7324476 | AY2: 平均汇率 | AZ2: =AVERAGE(AZ6:AZ31) -> 6.7948609 | BD2: 平均汇率 | BE2: =AVERAGE(BE6:BE31) -> 6.9620619 | BI2: 平均汇率 | BJ2: =AVERAGE(BJ6:BJ31) -> 7.1286938 | BN2: 平均汇率 | BO2: =AVERAGE(BO6:BO31) -> 7.1627864 | BS2: 平均汇率 | BT2: =AVERAGE(BT6:BT31) -> 6.9832591 | BW2: 平均汇率 | BX2: =AVERAGE(BX6:BX31) -> 6.7975813 | CA2: 平均汇率 | CB2: =AVERAGE(CB6:CB31) -> 6.829585 | CE2: 平均汇率 | CF2: =AVERAGE(CF6:CF31) -> 6.8981522 | CI2: 平均汇率 | CJ2: =AVERAGE(CJ6:CJ31) -> 6.8851684 | CM2: 平均汇率 | CN2: =AVERAGE(CN6:CN31) -> 6.991195 | CQ2: 平均汇率 | CR2: =AVERAGE(CR6:CR31) -> 7.149205 | CU2: 平均汇率 | CV2: =AVERAGE(CV6:CV31) -> 7.1618667 | CY2: 平均汇率 | CZ2: =AVERAGE(CZ6:CZ31) -> 7.1732696 | DC2: 平均汇率 | DD2: =AVERAGE(DD6:DD31) -> 7.183895 | DG2: 平均汇率 | DH2: =AVERAGE(DH6:DH31) -> 7.1786235 | DK2: 平均汇率 | DL2: =AVERAGE(DL6:DL31) -> 7.1543591 | DO2: 平均汇率 | DP2: =AVERAGE(DP6:DP31) -> 7.103881 | DS2: 平均汇率 | DT2: =AVERAGE(DT6:DT31) -> 7.1060857 | DW2: 平均汇率 | DX2: =AVERAGE(DX6:DX31) -> 7.1050937 | EA2: 平均汇率 | EB2: =AVERAGE(EB6:EB31) -> 7.0978 | EE2: 平均汇率 | EF2: =AVERAGE(EF6:EF31) -> 7.10066 | EI2: 平均汇率 | EJ2: =AVERAGE(EJ6:EJ31) -> 7.105665 | EM2: 平均汇率 | EN2: =AVERAGE(EN6:EN31) -> 7.1161947 | EQ2: 平均汇率 | ER2: =AVERAGE(ER6:ER31) -> 7.1315522 | EU2: 平均汇率 | EV2: =AVERAGE(EV6:EV31) -> 7.1342364 | EY2: 平均汇率 | EZ2: =AVERAGE(EZ6:EZ31) -> 7.0790579 | FC2: 平均汇率 | FD2: =AVERAGE(FD6:FD31) -> 7.1058 | FG2: 平均汇率 | FH2: =AVERAGE(FH6:FH31) -> 7.1729095 | FK2: 平均汇率 | FL2: =AVERAGE(FL6:FL31) -> 7.18865 | FO2: 平均汇率 | FP2: =AVERAGE(FP6:FP31) -> 7.1882667 | FS2: 平均汇率 | FT2: =AVERAGE(FT6:FT31) -> 7.1711444 | FW2: 平均汇率 | FX2: =AVERAGE(FX6:FX31) -> 7.1737238 | GA2: 平均汇率 | GB2: =AVERAGE(GB6:GB31) -> 7.2033714 | GE2: 平均汇率 | GF2: =AVERAGE(GF6:GF31) -> 7.1950474 | GI2: 平均汇率 | GJ2: =AVERAGE(GJ6:GJ31) -> 7.175685 | GM2: 平均汇率 | GN2: =AVERAGE(GN6:GN31) -> 7.1490913 | GQ2: 平均汇率 | GR2: =AVERAGE(GR6:GR31) -> 7.1309381 | GU2: 平均汇率 | GV2: =AVERAGE(GV6:GV31) -> 7.1068182 | GY2: 平均汇率 | GZ2: =AVERAGE(GZ6:GZ31) -> 7.0948059 | HC2: 平均汇率 | HD2: =AVERAGE(HD6:HD31) -> 7.0848 | HG2: 平均汇率 | HH2: =AVERAGE(HH6:HH31) -> 7.0593478 | HK2: 平均汇率 | HL2: =AVERAGE(HL6:HL31) -> 7.00156 | HO2: 平均汇率 | HP2: =AVERAGE(HP6:HP31) -> 6.94615 | HS2: 平均汇率 | HT2: =AVERAGE(HT6:HT31) -> 6.9036909 | HW2: 平均汇率 | HX2: =AVERAGE(HX6:HX31) -> 6.8683143 | IA2: 平均汇率 | IB2: =AVERAGE(IB6:IB31) -> 6.8385167 | IE2: 平均汇率 | IF2: =AVERAGE(IF6:IF31) -> 6.8153762
J3: CNY兑 USD | K3: 期末汇率 | L3: =1/L8 -> 0.15689966 | M3: =ROUND(L3,12) -> 0.15689966 | O3: CNY兑 USD | P3: 期末汇率 | Q3: =1/Q6 -> 0.15750016 | R3: =ROUND(Q3,12) -> 0.15750016 | T3: CNY兑 USD | U3: 期末汇率 | V3: =1/V6 -> 0.15817279 | W3: =ROUND(V3,12) -> 0.15817279 | Y3: CNY兑 USD | Z3: 期末汇率 | AA3: =1/AA6 -> 0.15752497 | AB3: =ROUND(AA3,12) -> 0.15752497 | AD3: CNY兑 USD | AE3: 期末汇率 | AF3: =1/AF6 -> 0.1511099 | AG3: =ROUND(AF3,12) -> 0.1511099 | AI3: CNY兑 USD | AJ3: 期末汇率 | AK3: =1/AK6 -> 0.15013437 | AL3: =ROUND(AK3,12) -> 0.15013437 | AN3: CNY兑 USD | AO3: 期末汇率 | AP3: =1/AP6 -> 0.14900021 | AQ3: =ROUND(AP3,12) -> 0.14900021 | AS3: CNY兑 USD | AT3: 期末汇率 | AU3: =1/AU6 -> 0.14828655 | AV3: =ROUND(AU3,12) -> 0.14828655 | AX3: CNY兑 USD | AY3: 期末汇率 | AZ3: =1/AZ6 -> 0.14512524 | BA3: =ROUND(AZ3,12) -> 0.14512524 | BC3: CNY兑 USD | BD3: 期末汇率 | BE3: =1/BE6 -> 0.14084904 | BF3: =ROUND(BE3,12) -> 0.14084904 | BH3: CNY兑 USD | BI3: 期末汇率 | BJ3: =1/BJ6 -> 0.13933787 | BM3: CNY兑 USD | BN3: 期末汇率 | BO3: =1/BO6 -> 0.13933592 | BP3: =ROUND(BO3,12) -> 0.13933592 | BR3: CNY兑 USD | BS3: 期末汇率 | BT3: =1/BT6 -> 0.14358326 | BU3: =ROUND(BT3,12) -> 0.14358326 | BV3: CNY兑 USD | BW3: 期末汇率 | BX3: =1/BX6 -> 0.14792024 | BY3: =ROUND(BX3,12) -> 0.14792024 | BZ3: CNY兑 USD | CA3: 期末汇率 | CB3: =1/CB6 -> 0.14384557 | CD3: CNY兑 USD | CE3: 期末汇率 | CF3: =1/CF6 -> 0.1455244 | CH3: CNY兑 USD | CI3: 期末汇率 | CJ3: =1/CJ6 -> 0.14442519 | CL3: CNY兑 USD | CM3: 期末汇率 | CN3: =1/CN6 -> 0.14120106 | CP3: CNY兑 USD | CQ3: 期末汇率 | CR3: =1/CR6 -> 0.13839298 | CT3: CNY兑 USD | CU3: 期末汇率 | CV3: =1/CV6 -> 0.14024262 | CX3: CNY兑 USD | CY3: 期末汇率 | CZ3: =1/CZ6 -> 0.13925443 | DB3: CNY兑 USD | DC3: 期末汇率 | DD3: =1/DD6 -> 0.13927965 | DF3: CNY兑 USD | DG3: 期末汇率 | DH3: =1/DH6 -> 0.13931651 | DJ3: CNY兑 USD | DK3: 期末汇率 | DL3: =1/DL6 -> 0.14080937 | DN3: CNY兑 USD | DO3: 期末汇率 | DP3: =1/DP6 -> 0.14118909 | DR3: CNY兑 USD | DS3: 期末汇率 | DT3: =1/DT6 -> 0.14073605 | DV3: CNY兑 USD | DW3: 期末汇率 | DX3: =1/DX6 -> 0.14077369 | DZ3: CNY兑 USD | EA3: 期末汇率 | EB3: =1/EB6 -> 0.14094433 | ED3: CNY兑 USD | EE3: 期末汇率 | EF3: =1/EF6 -> 0.14072021 | EH3: CNY兑 USD | EI3: 期末汇率 | EJ3: =1/EJ6 -> 0.14067072 | EL3: CNY兑 USD | EM3: 期末汇率 | EN3: =1/EN6 -> 0.14031543 | EP3: CNY兑 USD | EQ3: 期末汇率 | ER3: =1/ER6 -> 0.14016203 | ET3: CNY兑 USD | EU3: 期末汇率 | EV3: =1/EV6 -> 0.14059952 | EX3: CNY兑 USD | EY3: 期末汇率 | EZ3: =1/EZ6 -> 0.14270628 | FB3: CNY兑 USD | FC3: 期末汇率 | FD3: =1/FD6 -> 0.14035088 | FF3: CNY兑 USD | FG3: 期末汇率 | FH3: =1/FH6 -> 0.13912656 | FJ3: CNY兑 USD | FK3: 期末汇率 | FL3: =1/FL6 -> 0.13911302 | FN3: CNY兑 USD | FO3: 期末汇率 | FP3: =1/FP6 -> 0.13910334 | FR3: CNY兑 USD | FS3: 期末汇率 | FT3: =1/FT6 -> 0.13939614 | FV3: CNY兑 USD | FW3: 期末汇率 | FX3: =1/FX6 -> 0.13931069 | FZ3: CNY兑 USD | GA3: 期末汇率 | GB3: =1/GB6 -> 0.13886189 | GD3: CNY兑 USD | GE3: 期末汇率 | GF3: =1/GF6 -> 0.13918272 | GH3: CNY兑 USD | GI3: 期末汇率 | GJ3: =1/GJ6 -> 0.13969212 | GL3: CNY兑 USD | GM3: 期末汇率 | GN3: =1/GN6 -> 0.13987188 | GP3: CNY兑 USD | GQ3: 期末汇率 | GR3: =1/GR6 -> 0.14078558 | GT3: CNY兑 USD | GU3: 期末汇率 | GV3: =1/GV6 -> 0.14073605 | GX3: CNY兑 USD | GY3: 期末汇率 | GZ3: =1/GZ6 -> 0.14108352 | HB3: CNY兑 USD | HC3: 期末汇率 | HD3: =1/HD6 -> 0.14126489 | HF3: CNY兑 USD | HG3: 期末汇率 | HH3: =1/HH6 -> 0.1422718 | HJ3: CNY兑 USD | HK3: 期末汇率 | HL3: =1/HL6 -> 0.14351732 | HN3: CNY兑 USD | HO3: 期末汇率 | HP3: =1/HP6 -> 0.14445022 | HR3: CNY兑 USD | HS3: 期末汇率 | HT3: =1/HT6 -> 0.1445212 | HV3: CNY兑 USD | HW3: 期末汇率 | HX3: =1/HX6 -> 0.14571312 | HZ3: CNY兑 USD | IA3: 期末汇率 | IB3: =1/IB6 -> 0.14667918 | ID3: CNY兑 USD | IE3: 期末汇率 | IF3: =1/IF6 -> 0.14682347
K4: 平均汇率 | L4: =1/AVERAGE(L8:L31) -> 0.15698916 | M4: =ROUND(L4,12) -> 0.15698916 | P4: 平均汇率 | Q4: =1/AVERAGE(Q6:Q31) -> 0.1571307 | R4: =ROUND(Q4,12) -> 0.1571307 | U4: 平均汇率 | V4: =1/AVERAGE(V6:V31) -> 0.15755366 | W4: =ROUND(V4,12) -> 0.15755366 | Z4: 平均汇率 | AA4: =1/AVERAGE(AA6:AA31) -> 0.15758649 | AB4: =ROUND(AA4,12) -> 0.15758649 | AE4: 平均汇率 | AF4: =1/AVERAGE(AF6:AF31) -> 0.155569 | AG4: =ROUND(AF4,12) -> 0.155569 | AJ4: 平均汇率 | AK4: =1/AVERAGE(AK6:AK31) -> 0.14909515 | AL4: =ROUND(AK4,12) -> 0.14909515 | AO4: 平均汇率 | AP4: =1/AVERAGE(AP6:AP31) -> 0.14927315 | AQ4: =ROUND(AP4,12) -> 0.14927315 | AT4: 平均汇率 | AU4: =1/AVERAGE(AU6:AU31) -> 0.14853439 | AV4: =ROUND(AU4,12) -> 0.14853439 | AY4: 平均汇率 | AZ4: =1/AVERAGE(AZ6:AZ31) -> 0.14717005 | BA4: =ROUND(AZ4,12) -> 0.14717005 | BD4: 平均汇率 | BE4: =1/AVERAGE(BE6:BE31) -> 0.14363561 | BF4: =ROUND(BE4,12) -> 0.14363561 | BI4: 平均汇率 | BJ4: =1/AVERAGE(BJ6:BJ31) -> 0.14027815 | BN4: 平均汇率 | BO4: =1/AVERAGE(BO6:BO31) -> 0.13961047 | BP4: =ROUND(BO4,12) -> 0.13961047 | BS4: 平均汇率 | BT4: =1/AVERAGE(BT6:BT31) -> 0.14319961 | BU4: =ROUND(BT4,12) -> 0.14319961 | BW4: 平均汇率 | BX4: =1/AVERAGE(BX6:BX31) -> 0.14711115 | BY4: =ROUND(BX4,12) -> 0.14711115 | CA4: 平均汇率 | CB4: =1/AVERAGE(CB6:CB31) -> 0.14642178 | CE4: 平均汇率 | CF4: =1/AVERAGE(CF6:CF31) -> 0.14496636 | CI4: 平均汇率 | CJ4: =1/AVERAGE(CJ6:CJ31) -> 0.14523973 | CM4: 平均汇率 | CN4: =1/AVERAGE(CN6:CN31) -> 0.14303706 | CQ4: 平均汇率 | CR4: =1/AVERAGE(CR6:CR31) -> 0.13987569 | CU4: 平均汇率 | CV4: =1/AVERAGE(CV6:CV31) -> 0.1396284 | CY4: 平均汇率 | CZ4: =1/AVERAGE(CZ6:CZ31) -> 0.13940644 | DC4: 平均汇率 | DD4: =1/AVERAGE(DD6:DD31) -> 0.13920025 | DG4: 平均汇率 | DH4: =1/AVERAGE(DH6:DH31) -> 0.13930247 | DK4: 平均汇率 | DL4: =1/AVERAGE(DL6:DL31) -> 0.13977492 | DO4: 平均汇率 | DP4: =1/AVERAGE(DP6:DP31) -> 0.14076812 | DS4: 平均汇率 | DT4: =1/AVERAGE(DT6:DT31) -> 0.14072445 | DW4: 平均汇率 | DX4: =1/AVERAGE(DX6:DX31) -> 0.1407441 | EA4: 平均汇率 | EB4: =1/AVERAGE(EB6:EB31) -> 0.14088873 | EE4: 平均汇率 | EF4: =1/AVERAGE(EF6:EF31) -> 0.14083198 | EI4: 平均汇率 | EJ4: =1/AVERAGE(EJ6:EJ31) -> 0.14073278 | EM4: 平均汇率 | EN4: =1/AVERAGE(EN6:EN31) -> 0.14052454 | EQ4: 平均汇率 | ER4: =1/AVERAGE(ER6:ER31) -> 0.14022193 | EU4: 平均汇率 | EV4: =1/AVERAGE(EV6:EV31) -> 0.14016917 | EY4: 平均汇率 | EZ4: =1/AVERAGE(EZ6:EZ31) -> 0.14126173 | FC4: 平均汇率 | FD4: =1/AVERAGE(FD6:FD31) -> 0.14073011 | FG4: 平均汇率 | FH4: =1/AVERAGE(FH6:FH31) -> 0.13941344 | FK4: 平均汇率 | FL4: =1/AVERAGE(FL6:FL31) -> 0.13910818 | FO4: 平均汇率 | FP4: =1/AVERAGE(FP6:FP31) -> 0.1391156 | FS4: 平均汇率 | FT4: =1/AVERAGE(FT6:FT31) -> 0.13944776 | FW4: 平均汇率 | FX4: =1/AVERAGE(FX6:FX31) -> 0.13939762 | GA4: 平均汇率 | GB4: =1/AVERAGE(GB6:GB31) -> 0.13882388 | GE4: 平均汇率 | GF4: =1/AVERAGE(GF6:GF31) -> 0.13898449 | GI4: 平均汇率 | GJ4: =1/AVERAGE(GJ6:GJ31) -> 0.13935952 | GM4: 平均汇率 | GN4: =1/AVERAGE(GN6:GN31) -> 0.13987792 | GQ4: 平均汇率 | GR4: =1/AVERAGE(GR6:GR31) -> 0.140234 | GU4: 平均汇率 | GV4: =1/AVERAGE(GV6:GV31) -> 0.14070995 | GY4: 平均汇率 | GZ4: =1/AVERAGE(GZ6:GZ31) -> 0.14094818 | HC4: 平均汇率 | HD4: =1/AVERAGE(HD6:HD31) -> 0.14114724 | HG4: 平均汇率 | HH4: =1/AVERAGE(HH6:HH31) -> 0.14165615 | HK4: 平均汇率 | HL4: =1/AVERAGE(HL6:HL31) -> 0.14282531 | HO4: 平均汇率 | HP4: =1/AVERAGE(HP6:HP31) -> 0.14396464 | HS4: 平均汇率 | HT4: =1/AVERAGE(HT6:HT31) -> 0.14485005 | HW4: 平均汇率 | HX4: =1/AVERAGE(HX6:HX31) -> 0.14559613 | IA4: 平均汇率 | IB4: =1/AVERAGE(IB6:IB31) -> 0.14623054 | IE4: 平均汇率 | IF4: =1/AVERAGE(IF6:IF31) -> 0.14672704
A5: 日期 | B5: 美元 | F5: 日期 | G5: 美元 | J5: 日期 | K5: 美元 | O5: 日期 | P5: 美元 | T5: 日期 | U5: 美元 | Y5: 日期 | Z5: 美元 | AD5: 日期 | AE5: 美元 | AI5: 日期 | AJ5: 美元 | AN5: 日期 | AO5: 美元 | AS5: 日期 | AT5: 美元 | AX5: 日期 | AY5: 美元 | BC5: 日期 | BD5: 美元 | BH5: 日期 | BI5: 美元 | BM5: 日期 | BN5: 美元 | BR5: 日期 | BS5: 美元 | BV5: 日期 | BW5: 美元 | CA5: 日期 | CB5: 美元 | CE5: 日期 | CF5: 美元 | CI5: 日期 | CJ5: 美元 | CM5: 日期 | CN5: 美元 | CQ5: 日期 | CR5: 美元 | CU5: 日期 | CV5: 美元 | CY5: 日期 | CZ5: 美元 | DC5: 日期 | DD5: 美元 | DG5: 日期 | DH5: 美元 | DK5: 日期 | DL5: 美元 | DO5: 日期 | DP5: 美元 | DS5: 日期 | DT5: 美元 | DW5: 日期 | DX5: 美元 | EA5: 日期 | EB5: 美元 | EE5: 日期 | EF5: 美元 | EI5: 日期 | EJ5: 美元 | EM5: 日期 | EN5: 美元 | EQ5: 日期 | ER5: 美元 | EU5: 日期 | EV5: 美元 | EY5: 日期 | EZ5: 美元 | FC5: 日期 | FD5: 美元 | FG5: 日期 | FH5: 美元 | FK5: 日期 | FL5: 美元 | FO5: 日期 | FP5: 美元 | FS5: 日期 | FT5: 美元 | FW5: 日期 | FX5: 美元 | GA5: 日期 | GB5: 美元 | GE5: 日期 | GF5: 美元 | GI5: 日期 | GJ5: 美元 | GM5: 日期 | GN5: 美元 | GQ5: 日期 | GR5: 美元 | GU5: 日期 | GV5: 美元 | GY5: 日期 | GZ5: 美元 | HC5: 日期 | HD5: 美元 | HG5: 日期 | HH5: 美元 | HK5: 日期 | HL5: 美元 | HO5: 日期 | HP5: 美元 | HS5: 日期 | HT5: 美元 | HW5: 日期 | HX5: 美元 | IA5: 日期 | IB5: 美元 | IE5: 日期 | IF5: 美元
A6: ='欧元 '!A6 -> 2021-10-29 | B6: 639.07 | C6: =B6/100 -> 6.3907 | F6: 2021-11-30 | G6: 637.94 | H6: =G6/100 -> 6.3794 | J6: 2021-12-31 | K6: 637.57 | L6: =K6/100 -> 6.3757 | O6: 2022-01-21 | P6: 634.92 | Q6: =P6/100 -> 6.3492 | T6: 2022-02-28 | U6: 632.22 | V6: =U6/100 -> 6.3222 | Y6: 2022-03-31 | Z6: 634.82 | AA6: =Z6/100 -> 6.3482 | AD6: 2022-04-29 | AE6: 661.77 | AF6: =AE6/100 -> 6.6177 | AI6: 2022-05-31 | AJ6: 666.07 | AK6: =AJ6/100 -> 6.6607 | AN6: 2022-06-30 | AO6: 671.14 | AP6: =AO6/100 -> 6.7114 | AS6: 2022-07-29 | AT6: 674.37 | AU6: =AT6/100 -> 6.7437 | AX6: 2022-08-31 | AY6: 689.06 | AZ6: =AY6/100 -> 6.8906 | BC6: 2022-09-30 | BD6: 709.98 | BE6: =BD6/100 -> 7.0998 | BH6: 2022-10-31 | BI6: 717.68 | BJ6: =BI6/100 -> 7.1768 | BM6: 2022-11-30 | BN6: 717.69 | BO6: =BN6/100 -> 7.1769 | BR6: 2022-12-30 | BS6: 696.46 | BT6: =BS6/100 -> 6.9646 | BV6: 2023-01-31 | BW6: 676.04 | BX6: =BW6/100 -> 6.7604 | CA6: 44985 | CB6: 6.9519 | CE6: 45016 | CF6: 6.8717 | CI6: 45044 | CJ6: 6.924 | CM6: 45077 | CN6: 7.0821 | CQ6: 45107 | CR6: 7.2258 | CU6: 45138 | CV6: 7.1305 | CY6: 45169 | CZ6: 7.1811 | DC6: 45197 | DD6: 7.1798 | DG6: 45230 | DH6: 7.1779 | DK6: 45260 | DL6: 7.1018 | DO6: 45289 | DP6: 7.0827 | DS6: 45321 | DT6: 7.1055 | DW6: 45351 | DX6: 7.1036 | EA6: 45380 | EB6: 7.095 | EE6: 45412 | EF6: 7.1063 | EI6: 45443 | EJ6: 7.1088 | EM6: 45471 | EN6: 7.1268 | EQ6: 45504 | ER6: 7.1346 | EU6: 45534 | EV6: 7.1124 | EY6: 45565 | EZ6: 7.0074 | FC6: 45596 | FD6: 7.125 | FG6: 45625 | FH6: 7.1877 | FK6: 45657 | FL6: 7.1884 | FO6: 45674 | FP6: 7.1889 | FS6: 45716 | FT6: 7.1738 | FW6: 45747 | FX6: 7.1782 | GA6: 45777 | GB6: 7.2014 | GE6: 45807 | GF6: 7.1848 | GI6: 45838 | GJ6: 7.1586 | GM6: 45869 | GN6: 7.1494 | GQ6: 45898 | GR6: 7.103 | GU6: 45930 | GV6: 7.1055 | GY6: 45961 | GZ6: 7.088 | HC6: 45989 | HD6: 7.0789 | HG6: 46022 | HH6: 7.0288 | HK6: 46052 | HL6: 6.9678 | HO6: 46080 | HP6: 6.9228 | HS6: 46112 | HT6: 6.9194 | HW6: 46142 | HX6: 6.8628 | IA6: 46171 | IB6: 6.8176 | IE6: 46203 | IF6: 6.8109
A7: ='欧元 '!A7 -> 2021-10-28 | B7: 639.57 | C7: =B7/100 -> 6.3957 | F7: 2021-11-29 | G7: 638.72 | H7: =G7/100 -> 6.3872 | J7: 2021-12-30 | K7: 636.74 | L7: =K7/100 -> 6.3674 | O7: 2022-01-20 | P7: 634.85 | Q7: =P7/100 -> 6.3485 | T7: 2022-02-25 | U7: 633.46 | V7: =U7/100 -> 6.3346 | Y7: 2022-03-30 | Z7: 635.66 | AA7: =Z7/100 -> 6.3566 | AD7: 2022-04-28 | AE7: 656.28 | AF7: =AE7/100 -> 6.5628 | AI7: 2022-05-30 | AJ7: 670.48 | AK7: =AJ7/100 -> 6.7048 | AN7: 2022-06-29 | AO7: 670.35 | AP7: =AO7/100 -> 6.7035 | AS7: 2022-07-28 | AT7: 674.11 | AU7: =AT7/100 -> 6.7411 | AX7: 2022-08-30 | AY7: 688.02 | AZ7: =AY7/100 -> 6.8802 | BC7: 2022-09-29 | BD7: 711.02 | BE7: =BD7/100 -> 7.1102 | BH7: 2022-10-28 | BI7: 716.98 | BJ7: =BI7/100 -> 7.1698 | BM7: 2022-11-29 | BN7: 719.89 | BO7: =BN7/100 -> 7.1989 | BR7: 2022-12-29 | BS7: 697.93 | BT7: =BS7/100 -> 6.9793 | BV7: 2023-01-30 | BW7: 676.26 | BX7: =BW7/100 -> 6.7626 | CA7: 44984 | CB7: 6.9572 | CE7: 45015 | CF7: 6.8886 | CI7: 45043 | CJ7: 6.9207 | CM7: 45076 | CN7: 7.0818 | CQ7: 45106 | CR7: 7.2208 | CU7: 45135 | CV7: 7.1338 | CY7: 45168 | CZ7: 7.1816 | DC7: 45196 | DD7: 7.1717 | DG7: 45229 | DH7: 7.1781 | DK7: 45259 | DL7: 7.1031 | DO7: 45288 | DP7: 7.0974 | DS7: 45320 | DT7: 7.1097 | DW7: 45350 | DX7: 7.1075 | EA7: 45379 | EB7: 7.0948 | EE7: 45411 | EF7: 7.1066 | EI7: 45442 | EJ7: 7.1111 | EM7: 45470 | EN7: 7.127 | EQ7: 45503 | ER7: 7.1364 | EU7: 45533 | EV7: 7.1299 | EY7: 45562 | EZ7: 7.0101 | FC7: 45595 | FD7: 7.139 | FG7: 45624 | FH7: 7.1894 | FK7: 45656 | FL7: 7.1889 | FO7: 45673 | FP7: 7.1881 | FS7: 45715 | FT7: 7.174 | FW7: 45744 | FX7: 7.1752 | GA7: 45776 | GB7: 7.2029 | GE7: 45806 | GF7: 7.1907 | GI7: 45835 | GJ7: 7.1627 | GM7: 45868 | GN7: 7.1441 | GQ7: 45897 | GR7: 7.1063 | GU7: 45929 | GV7: 7.1089 | GY7: 45960 | GZ7: 7.0864 | HC7: 45988 | HD7: 7.0779 | HG7: 46021 | HH7: 7.0348 | HK7: 46051 | HL7: 6.9771 | HO7: 46079 | HP7: 6.9228 | HS7: 46111 | HT7: 6.9223 | HW7: 46141 | HX7: 6.8608 | IA7: 46170 | IB7: 6.824 | IE7: 46202 | IF7: 6.8175
A8: ='欧元 '!A8 -> 2021-10-27 | B8: 638.56 | C8: =B8/100 -> 6.3856 | F8: 2021-11-26 | G8: 639.36 | H8: =G8/100 -> 6.3936 | J8: 2021-12-29 | K8: 637.35 | L8: =K8/100 -> 6.3735 | O8: 2022-01-19 | P8: 636.24 | Q8: =P8/100 -> 6.3624 | T8: 2022-02-24 | U8: 632.8 | V8: =U8/100 -> 6.328 | Y8: 2022-03-29 | Z8: 636.4 | AA8: =Z8/100 -> 6.364 | AD8: 2022-04-27 | AE8: 655.98 | AF8: =AE8/100 -> 6.5598 | AI8: 2022-05-27 | AJ8: 673.87 | AK8: =AJ8/100 -> 6.7387 | AN8: 2022-06-28 | AO8: 669.3 | AP8: =AO8/100 -> 6.693 | AS8: 2022-07-27 | AT8: 677.31 | AU8: =AT8/100 -> 6.7731 | AX8: 2022-08-29 | AY8: 686.98 | AZ8: =AY8/100 -> 6.8698 | BC8: 2022-09-28 | BD8: 711.07 | BE8: =BD8/100 -> 7.1107 | BH8: 2022-10-27 | BI8: 715.7 | BJ8: =BI8/100 -> 7.157 | BM8: 2022-11-28 | BN8: 716.17 | BO8: =BN8/100 -> 7.1617 | BR8: 2022-12-28 | BS8: 696.81 | BT8: =BS8/100 -> 6.9681 | BV8: 2023-01-20 | BW8: 677.02 | BX8: =BW8/100 -> 6.7702 | CA8: 44981 | CB8: 6.8942 | CE8: 45014 | CF8: 6.8771 | CI8: 45042 | CJ8: 6.9237 | CM8: 45075 | CN8: 7.0575 | CQ8: 45105 | CR8: 7.2101 | CU8: 45134 | CV8: 7.1265 | CY8: 45167 | CZ8: 7.1851 | DC8: 45195 | DD8: 7.1727 | DG8: 45226 | DH8: 7.1782 | DK8: 45258 | DL8: 7.1132 | DO8: 45287 | DP8: 7.1002 | DS8: 45317 | DT8: 7.1074 | DW8: 45349 | DX8: 7.1057 | EA8: 45378 | EB8: 7.0946 | EE8: 45408 | EF8: 7.1056 | EI8: 45441 | EJ8: 7.1106 | EM8: 45469 | EN8: 7.1248 | EQ8: 45502 | ER8: 7.1316 | EU8: 45532 | EV8: 7.1216 | EY8: 45561 | EZ8: 7.0354 | FC8: 45594 | FD8: 7.1283 | FG8: 45623 | FH8: 7.1982 | FK8: 45653 | FL8: 7.1893 | FO8: 45672 | FP8: 7.1883 | FS8: 45714 | FT8: 7.1732 | FW8: 45743 | FX8: 7.1763 | GA8: 45775 | GB8: 7.2043 | GE8: 45805 | GF8: 7.1894 | GI8: 45834 | GJ8: 7.162 | GM8: 45867 | GN8: 7.1511 | GQ8: 45896 | GR8: 7.1108 | GU8: 45926 | GV8: 7.1152 | GY8: 45959 | GZ8: 7.0843 | HC8: 45987 | HD8: 7.0796 | HG8: 46020 | HH8: 7.0331 | HK8: 46050 | HL8: 6.9755 | HO8: 46078 | HP8: 6.9321 | HS8: 46108 | HT8: 6.9141 | HW8: 46140 | HX8: 6.8589 | IA8: 46169 | IB8: 6.8291 | IE8: 46199 | IF8: 6.8166
A9: ='欧元 '!A9 -> 2021-10-26 | B9: 638.9 | C9: =B9/100 -> 6.389 | F9: 2021-11-25 | G9: 639.8 | H9: =G9/100 -> 6.398 | J9: 2021-12-28 | K9: 637.28 | L9: =K9/100 -> 6.3728 | O9: 2022-01-18 | P9: 635.21 | Q9: =P9/100 -> 6.3521 | T9: 2022-02-23 | U9: 633.13 | V9: =U9/100 -> 6.3313 | Y9: 2022-03-28 | Z9: 637.32 | AA9: =Z9/100 -> 6.3732 | AD9: 2022-04-26 | AE9: 655.9 | AF9: =AE9/100 -> 6.559 | AI9: 2022-05-26 | AJ9: 667.66 | AK9: =AJ9/100 -> 6.6766 | AN9: 2022-06-27 | AO9: 668.5 | AP9: =AO9/100 -> 6.685 | AS9: 2022-07-26 | AT9: 674.83 | AU9: =AT9/100 -> 6.7483 | AX9: 2022-08-26 | AY9: 684.86 | AZ9: =AY9/100 -> 6.8486 | BC9: 2022-09-27 | BD9: 707.22 | BE9: =BD9/100 -> 7.0722 | BH9: 2022-10-26 | BI9: 716.38 | BJ9: =BI9/100 -> 7.1638 | BM9: 2022-11-25 | BN9: 713.39 | BO9: =BN9/100 -> 7.1339 | BR9: 2022-12-27 | BS9: 695.46 | BT9: =BS9/100 -> 6.9546 | BV9: 2023-01-19 | BW9: 676.74 | BX9: =BW9/100 -> 6.7674 | CA9: 44980 | CB9: 6.9028 | CE9: 45013 | CF9: 6.8749 | CI9: 45041 | CJ9: 6.8847 | CM9: 45072 | CN9: 7.076 | CQ9: 45104 | CR9: 7.2098 | CU9: 45133 | CV9: 7.1295 | CY9: 45166 | CZ9: 7.1856 | DC9: 45194 | DD9: 7.1727 | DG9: 45225 | DH9: 7.1784 | DK9: 45257 | DL9: 7.1159 | DO9: 45286 | DP9: 7.0965 | DS9: 45316 | DT9: 7.1044 | DW9: 45348 | DX9: 7.108 | EA9: 45377 | EB9: 7.0943 | EE9: 45407 | EF9: 7.1058 | EI9: 45440 | EJ9: 7.1101 | EM9: 45468 | EN9: 7.1225 | EQ9: 45499 | ER9: 7.127 | EU9: 45531 | EV9: 7.1249 | EY9: 45560 | EZ9: 7.0202 | FC9: 45593 | FD9: 7.1307 | FG9: 45622 | FH9: 7.191 | FK9: 45652 | FL9: 7.1897 | FO9: 45671 | FP9: 7.1878 | FS9: 45713 | FT9: 7.1726 | FW9: 45742 | FX9: 7.1754 | GA9: 45772 | GB9: 7.2066 | GE9: 45804 | GF9: 7.1876 | GI9: 45833 | GJ9: 7.1668 | GM9: 45866 | GN9: 7.1467 | GQ9: 45895 | GR9: 7.1188 | GU9: 45925 | GV9: 7.1118 | GY9: 45958 | GZ9: 7.0856 | HC9: 45986 | HD9: 7.0826 | HG9: 46017 | HH9: 7.0358 | HK9: 46049 | HL9: 6.9858 | HO9: 46077 | HP9: 6.9414 | HS9: 46107 | HT9: 6.9056 | HW9: 46139 | HX9: 6.8579 | IA9: 46168 | IB9: 6.8288 | IE9: 46198 | IF9: 6.8209
A10: ='欧元 '!A10 -> 2021-10-25 | B10: 639.24 | C10: =B10/100 -> 6.3924 | F10: 2021-11-24 | G10: 639.03 | H10: =G10/100 -> 6.3903 | J10: 2021-12-27 | K10: 636.86 | L10: =K10/100 -> 6.3686 | O10: 2022-01-17 | P10: 635.99 | Q10: =P10/100 -> 6.3599 | T10: 2022-02-22 | U10: 634.87 | V10: =U10/100 -> 6.3487 | Y10: 2022-03-25 | Z10: 637.39 | AA10: =Z10/100 -> 6.3739 | AD10: 2022-04-25 | AE10: 649.09 | AF10: =AE10/100 -> 6.4909 | AI10: 2022-05-25 | AJ10: 665.5 | AK10: =AJ10/100 -> 6.655 | AN10: 2022-06-24 | AO10: 670.0 | AP10: =AO10/100 -> 6.7 | AS10: 2022-07-25 | AT10: 675.43 | AU10: =AT10/100 -> 6.7543 | AX10: 2022-08-25 | AY10: 685.36 | AZ10: =AY10/100 -> 6.8536 | BC10: 2022-09-26 | BD10: 702.98 | BE10: =BD10/100 -> 7.0298 | BH10: 2022-10-25 | BI10: 716.68 | BJ10: =BI10/100 -> 7.1668 | BM10: 2022-11-24 | BN10: 712.01 | BO10: =BN10/100 -> 7.1201 | BR10: 2022-12-26 | BS10: 698.25 | BT10: =BS10/100 -> 6.9825 | BV10: 2023-01-18 | BW10: 676.02 | BX10: =BW10/100 -> 6.7602 | CA10: 44979 | CB10: 6.8759 | CE10: 45012 | CF10: 6.8714 | CI10: 45040 | CJ10: 6.8835 | CM10: 45071 | CN10: 7.0529 | CQ10: 45103 | CR10: 7.2056 | CU10: 45132 | CV10: 7.1406 | CY10: 45163 | CZ10: 7.1883 | DC10: 45191 | DD10: 7.1729 | DG10: 45224 | DH10: 7.1785 | DK10: 45254 | DL10: 7.1151 | DO10: 45285 | DP10: 7.101 | DS10: 45315 | DT10: 7.1053 | DW10: 45345 | DX10: 7.1064 | EA10: 45376 | EB10: 7.0996 | EE10: 45406 | EF10: 7.1048 | EI10: 45439 | EJ10: 7.1091 | EM10: 45467 | EN10: 7.1201 | EQ10: 45498 | ER10: 7.1321 | EU10: 45530 | EV10: 7.1139 | EY10: 45559 | EZ10: 7.051 | FC10: 45590 | FD10: 7.109 | FG10: 45621 | FH10: 7.1918 | FK10: 45651 | FL10: 7.1868 | FO10: 45670 | FP10: 7.1885 | FS10: 45712 | FT10: 7.1717 | FW10: 45741 | FX10: 7.1788 | GA10: 45771 | GB10: 7.2098 | GE10: 45803 | GF10: 7.1833 | GI10: 45832 | GJ10: 7.1656 | GM10: 45863 | GN10: 7.1419 | GQ10: 45894 | GR10: 7.1161 | GU10: 45924 | GV10: 7.1077 | GY10: 45957 | GZ10: 7.0881 | HC10: 45985 | HD10: 7.0847 | HG10: 46016 | HH10: 7.0392 | HK10: 46048 | HL10: 6.9843 | HO10: 46066 | HP10: 6.9398 | HS10: 46106 | HT10: 6.8911 | HW10: 46136 | HX10: 6.8674 | IA10: 46167 | IB10: 6.8318 | IE10: 46197 | IF10: 6.8195
A11: ='欧元 '!A11 -> 2021-10-22 | B11: 640.32 | C11: =B11/100 -> 6.4032 | F11: 2021-11-23 | G11: 639.29 | H11: =G11/100 -> 6.3929 | J11: 2021-12-24 | K11: 636.92 | L11: =K11/100 -> 6.3692 | O11: 2022-01-14 | P11: 636.77 | Q11: =P11/100 -> 6.3677 | T11: 2022-02-21 | U11: 634.01 | V11: =U11/100 -> 6.3401 | Y11: 2022-03-24 | Z11: 636.4 | AA11: =Z11/100 -> 6.364 | AD11: 2022-04-22 | AE11: 645.96 | AF11: =AE11/100 -> 6.4596 | AI11: 2022-05-24 | AJ11: 665.66 | AK11: =AJ11/100 -> 6.6566 | AN11: 2022-06-23 | AO11: 670.79 | AP11: =AO11/100 -> 6.7079 | AS11: 2022-07-22 | AT11: 675.22 | AU11: =AT11/100 -> 6.7522 | AX11: 2022-08-24 | AY11: 683.88 | AZ11: =AY11/100 -> 6.8388 | BC11: 2022-09-23 | BD11: 699.2 | BE11: =BD11/100 -> 6.992 | BH11: 2022-10-24 | BI11: 712.3 | BJ11: =BI11/100 -> 7.123 | BM11: 2022-11-23 | BN11: 712.81 | BO11: =BN11/100 -> 7.1281 | BR11: 2022-12-23 | BS11: 698.1 | BT11: =BS11/100 -> 6.981 | BV11: 2023-01-17 | BW11: 672.22 | BX11: =BW11/100 -> 6.7222 | CA11: 44978 | CB11: 6.8557 | CE11: 45009 | CF11: 6.8374 | CI11: 45037 | CJ11: 6.8752 | CM11: 45070 | CN11: 7.056 | CQ11: 45098 | CR11: 7.1795 | CU11: 45131 | CV11: 7.1451 | CY11: 45162 | CZ11: 7.1886 | DC11: 45190 | DD11: 7.173 | DG11: 45223 | DH11: 7.1786 | DK11: 45253 | DL11: 7.1212 | DO11: 45282 | DP11: 7.0953 | DS11: 45314 | DT11: 7.1117 | DW11: 45344 | DX11: 7.1018 | EA11: 45373 | EB11: 7.1004 | EE11: 45405 | EF11: 7.1059 | EI11: 45436 | EJ11: 7.1102 | EM11: 45464 | EN11: 7.1196 | EQ11: 45497 | ER11: 7.1358 | EU11: 45527 | EV11: 7.1358 | EY11: 45558 | EZ11: 7.0531 | FC11: 45589 | FD11: 7.1286 | FG11: 45618 | FH11: 7.1942 | FK11: 45650 | FL11: 7.1876 | FO11: 45667 | FP11: 7.1891 | FS11: 45709 | FT11: 7.1696 | FW11: 45740 | FX11: 7.178 | GA11: 45770 | GB11: 7.2116 | GE11: 45800 | GF11: 7.1919 | GI11: 45831 | GJ11: 7.171 | GM11: 45862 | GN11: 7.1385 | GQ11: 45891 | GR11: 7.1321 | GU11: 45923 | GV11: 7.1057 | GY11: 45954 | GZ11: 7.0928 | HC11: 45982 | HD11: 7.0875 | HG11: 46015 | HH11: 7.0471 | HK11: 46045 | HL11: 6.9929 | HO11: 46065 | HP11: 6.9457 | HS11: 46105 | HT11: 6.8943 | HW11: 46135 | HX11: 6.865 | IA11: 46164 | IB11: 6.8373 | IE11: 46196 | IF11: 6.8171
A12: ='欧元 '!A12 -> 2021-10-21 | B12: 638.9 | C12: =B12/100 -> 6.389 | F12: 2021-11-22 | G12: 639.52 | H12: =G12/100 -> 6.3952 | J12: 2021-12-23 | K12: 636.51 | L12: =K12/100 -> 6.3651 | O12: 2022-01-13 | P12: 635.42 | Q12: =P12/100 -> 6.3542 | T12: 2022-02-18 | U12: 633.43 | V12: =U12/100 -> 6.3343 | Y12: 2022-03-23 | Z12: 635.58 | AA12: =Z12/100 -> 6.3558 | AD12: 2022-04-21 | AE12: 640.98 | AF12: =AE12/100 -> 6.4098 | AI12: 2022-05-23 | AJ12: 667.56 | AK12: =AJ12/100 -> 6.6756 | AN12: 2022-06-22 | AO12: 671.09 | AP12: =AO12/100 -> 6.7109 | AS12: 2022-07-21 | AT12: 676.2 | AU12: =AT12/100 -> 6.762 | AX12: 2022-08-23 | AY12: 685.23 | AZ12: =AY12/100 -> 6.8523 | BC12: 2022-09-22 | BD12: 697.98 | BE12: =BD12/100 -> 6.9798 | BH12: 2022-10-21 | BI12: 711.86 | BJ12: =BI12/100 -> 7.1186 | BM12: 2022-11-22 | BN12: 716.67 | BO12: =BN12/100 -> 7.1667 | BR12: 2022-12-22 | BS12: 697.13 | BT12: =BS12/100 -> 6.9713 | BV12: 2023-01-16 | BW12: 671.35 | BX12: =BW12/100 -> 6.7135 | CA12: 44977 | CB12: 6.8643 | CE12: 45008 | CF12: 6.8709 | CI12: 45036 | CJ12: 6.8987 | CM12: 45069 | CN12: 7.0326 | CQ12: 45097 | CR12: 7.1596 | CU12: 45128 | CV12: 7.1456 | CY12: 45161 | CZ12: 7.1988 | DC12: 45189 | DD12: 7.1732 | DG12: 45222 | DH12: 7.1792 | DK12: 45252 | DL12: 7.1254 | DO12: 45281 | DP12: 7.1012 | DS12: 45313 | DT12: 7.1105 | DW12: 45343 | DX12: 7.103 | EA12: 45372 | EB12: 7.0942 | EE12: 45404 | EF12: 7.1043 | EI12: 45435 | EJ12: 7.1098 | EM12: 45463 | EN12: 7.1192 | EQ12: 45496 | ER12: 7.1334 | EU12: 45526 | EV12: 7.1228 | EY12: 45555 | EZ12: 7.0644 | FC12: 45588 | FD12: 7.1245 | FG12: 45617 | FH12: 7.1934 | FK12: 45649 | FL12: 7.187 | FO12: 45666 | FP12: 7.1886 | FS12: 45708 | FT12: 7.1712 | FW12: 45737 | FX12: 7.176 | GA12: 45769 | GB12: 7.2074 | GE12: 45799 | GF12: 7.1903 | GI12: 45828 | GJ12: 7.1695 | GM12: 45861 | GN12: 7.1414 | GQ12: 45890 | GR12: 7.1287 | GU12: 45922 | GV12: 7.1106 | GY12: 45953 | GZ12: 7.0918 | HC12: 45981 | HD12: 7.0905 | HG12: 46014 | HH12: 7.0523 | HK12: 46044 | HL12: 7.0019 | HO12: 46064 | HP12: 6.9438 | HS12: 46104 | HT12: 6.9041 | HW12: 46134 | HX12: 6.8635 | IA12: 46163 | IB12: 6.8349 | IE12: 46195 | IF12: 6.815
A13: ='欧元 '!A13 -> 2021-10-20 | B13: 640.69 | C13: =B13/100 -> 6.4069 | F13: 2021-11-19 | G13: 638.25 | H13: =G13/100 -> 6.3825 | J13: 2021-12-22 | K13: 637.03 | L13: =K13/100 -> 6.3703 | O13: 2022-01-12 | P13: 636.58 | Q13: =P13/100 -> 6.3658 | T13: 2022-02-17 | U13: 633.21 | V13: =U13/100 -> 6.3321 | Y13: 2022-03-22 | Z13: 636.64 | AA13: =Z13/100 -> 6.3664 | AD13: 2022-04-20 | AE13: 639.96 | AF13: =AE13/100 -> 6.3996 | AI13: 2022-05-20 | AJ13: 674.87 | AK13: =AJ13/100 -> 6.7487 | AN13: 2022-06-21 | AO13: 668.51 | AP13: =AO13/100 -> 6.6851 | AS13: 2022-07-20 | AT13: 674.65 | AU13: =AT13/100 -> 6.7465 | AX13: 2022-08-22 | AY13: 681.98 | AZ13: =AY13/100 -> 6.8198 | BC13: 2022-09-21 | BD13: 695.36 | BE13: =BD13/100 -> 6.9536 | BH13: 2022-10-20 | BI13: 711.88 | BJ13: =BI13/100 -> 7.1188 | BM13: 2022-11-21 | BN13: 712.56 | BO13: =BN13/100 -> 7.1256 | BR13: 2022-12-21 | BS13: 696.5 | BT13: =BS13/100 -> 6.965 | BV13: 2023-01-13 | BW13: 672.92 | BX13: =BW13/100 -> 6.7292 | CA13: 44974 | CB13: 6.8659 | CE13: 45007 | CF13: 6.8715 | CI13: 45035 | CJ13: 6.8731 | CM13: 45068 | CN13: 7.0157 | CQ13: 45096 | CR13: 7.1201 | CU13: 45127 | CV13: 7.1466 | CY13: 45160 | CZ13: 7.1992 | DC13: 45188 | DD13: 7.1733 | DG13: 45219 | DH13: 7.1793 | DK13: 45251 | DL13: 7.1406 | DO13: 45280 | DP13: 7.0966 | DS13: 45310 | DT13: 7.1167 | DW13: 45342 | DX13: 7.1068 | EA13: 45371 | EB13: 7.0968 | EE13: 45401 | EF13: 7.1046 | EI13: 45434 | EJ13: 7.1077 | EM13: 45462 | EN13: 7.1159 | EQ13: 45495 | ER13: 7.1335 | EU13: 45525 | EV13: 7.1307 | EY13: 45554 | EZ13: 7.0983 | FC13: 45587 | FD13: 7.1223 | FG13: 45616 | FH13: 7.1935 | FK13: 45646 | FL13: 7.1901 | FO13: 45665 | FP13: 7.1887 | FS13: 45707 | FT13: 7.1705 | FW13: 45736 | FX13: 7.1754 | GA13: 45768 | GB13: 7.2055 | GE13: 45798 | GF13: 7.1937 | GI13: 45827 | GJ13: 7.1729 | GM13: 45860 | GN13: 7.146 | GQ13: 45889 | GR13: 7.1384 | GU13: 45919 | GV13: 7.1128 | GY13: 45952 | GZ13: 7.0954 | HC13: 45980 | HD13: 7.0872 | HG13: 46013 | HH13: 7.0572 | HK13: 46043 | HL13: 7.0014 | HO13: 46063 | HP13: 6.9458 | HS13: 46101 | HT13: 6.8898 | HW13: 46133 | HX13: 6.8594 | IA13: 46162 | IB13: 6.8397 | IE13: 46191 | IF13: 6.813
A14: ='欧元 '!A14 -> 2021-10-19 | B14: 643.07 | C14: =B14/100 -> 6.4307 | F14: 2021-11-18 | G14: 638.03 | H14: =G14/100 -> 6.3803 | J14: 2021-12-21 | K14: 637.29 | L14: =K14/100 -> 6.3729 | O14: 2022-01-11 | P14: 636.84 | Q14: =P14/100 -> 6.3684 | T14: 2022-02-16 | U14: 634.63 | V14: =U14/100 -> 6.3463 | Y14: 2022-03-21 | Z14: 636.77 | AA14: =Z14/100 -> 6.3677 | AD14: 2022-04-19 | AE14: 637.2 | AF14: =AE14/100 -> 6.372 | AI14: 2022-05-19 | AJ14: 675.24 | AK14: =AJ14/100 -> 6.7524 | AN14: 2022-06-20 | AO14: 671.2 | AP14: =AO14/100 -> 6.712 | AS14: 2022-07-19 | AT14: 674.51 | AU14: =AT14/100 -> 6.7451 | AX14: 2022-08-19 | AY14: 680.65 | AZ14: =AY14/100 -> 6.8065 | BC14: 2022-09-20 | BD14: 694.68 | BE14: =BD14/100 -> 6.9468 | BH14: 2022-10-19 | BI14: 711.05 | BJ14: =BI14/100 -> 7.1105 | BM14: 2022-11-18 | BN14: 710.91 | BO14: =BN14/100 -> 7.1091 | BR14: 2022-12-20 | BS14: 698.61 | BT14: =BS14/100 -> 6.9861 | BV14: 2023-01-12 | BW14: 676.8 | BX14: =BW14/100 -> 6.768 | CA14: 44973 | CB14: 6.8519 | CE14: 45006 | CF14: 6.8763 | CI14: 45034 | CJ14: 6.8814 | CM14: 45065 | CN14: 7.0356 | CQ14: 45093 | CR14: 7.1289 | CU14: 45126 | CV14: 7.1486 | CY14: 45159 | CZ14: 7.1987 | DC14: 45187 | DD14: 7.1736 | DG14: 45218 | DH14: 7.1795 | DK14: 45250 | DL14: 7.1612 | DO14: 45279 | DP14: 7.0982 | DS14: 45309 | DT14: 7.1174 | DW14: 45341 | DX14: 7.1032 | EA14: 45370 | EB14: 7.0985 | EE14: 45400 | EF14: 7.102 | EI14: 45433 | EJ14: 7.1069 | EM14: 45461 | EN14: 7.1148 | EQ14: 45492 | ER14: 7.1315 | EU14: 45524 | EV14: 7.1325 | EY14: 45553 | EZ14: 7.087 | FC14: 45586 | FD14: 7.0982 | FG14: 45615 | FH14: 7.1911 | FK14: 45645 | FL14: 7.1911 | FO14: 45664 | FP14: 7.1879 | FS14: 45706 | FT14: 7.1697 | FW14: 45735 | FX14: 7.1697 | GA14: 45765 | GB14: 7.2069 | GE14: 45797 | GF14: 7.1931 | GI14: 45826 | GJ14: 7.1761 | GM14: 45859 | GN14: 7.1522 | GQ14: 45888 | GR14: 7.1359 | GU14: 45918 | GV14: 7.1085 | GY14: 45951 | GZ14: 7.093 | HC14: 45979 | HD14: 7.0856 | HG14: 46010 | HH14: 7.055 | HK14: 46042 | HL14: 7.0006 | HO14: 46062 | HP14: 6.9523 | HS14: 46100 | HT14: 6.8975 | HW14: 46132 | HX14: 6.8648 | IA14: 46161 | IB14: 6.8375 | IE14: 46190 | IF14: 6.8096
